Workbook

Sheet Deal_Master_Wide
A1: AUDIT & ELIGIBILITY | O1: DEAL CHARACTERISTICS | AJ1: FIRM, CLASSIFICATION & SOURCE STATUS | BI1: EVENT-YEAR MAP | BP1: FINANCIAL DATA — ENTER VALUES IN REPORTED CURRENCY, MILLIONS | EA1: PATENT DATA — UNIQUE FAMILIES / CITATION-WEIGHTED OUTPUT | EO1: PATENT MODERATORS | EU1: DERIVED DiD CHECKS
A2: Deal_ID | B2: Source_Row | C2: Initial_Group | D2: Initial_Treatment_Indicator | E2: Source_File | F2: Cross_File_Key | G2: Overlap_Flag | H2: Duplicate_Flag | I2: Multiple_Deal_Acquirer | J2: Acquirer_Deal_Count_in_File | K2: Manual_Review_Status | L2: Initial_Control_Transfer_Status | M2: Main_DiD_Decision | N2: Exclusion_Reason | O2: Announced_Date | P2: Completion_Date | Q2: Completion_Year | R2: Completion_Quarter | S2: Deal_Status | T2: Deal_Headline | U2: Deal_Type_Level_1 | V2: Deal_Subtype_Level_2 | W2: Deal_Subtype_Level_3 | X2: Deal_Country_s | Y2: Deal_Subcategory | Z2: Financial_Advisors | AA2: Legal_Advisors | AB2: Acquirer_Raw | AC2: Acquirer_Normalized | AD2: Target_Raw | AE2: Target_Normalized | AF2: Deal_Value_USD_m | AG2: Deal_Value_Raw | AH2: Description | AI2: Deal_Rationale | AJ2: Acquirer_Country | AK2: Target_Country | AL2: Cross_Border_Flag | AM2: Acquirer_Listed | AN2: Bloomberg_Ticker | AO2: ISIN | AP2: LEI | AQ2: Acquirer_Parent_Mapping | AR2: Target_Parent_Mapping | AS2: Patent_Search_Acquirer_Names | AT2: Patent_Search_Target_Names | AU2: Final_Classification | AV2: Classification_Confidence | AW2: Patent_Evidence | AX2: Pipeline_Evidence | AY2: Platform_Evidence | AZ2: R_and_D_Evidence | BA2: Commercial_or_Geographic_Evidence | BB2: Mixed_Motive_Flag | BC2: Classification_Notes | BD2: Deal_Validation_Source_URL | BE2: Financial_Currency | BF2: Financial_Data_Status | BG2: Patent_Data_Status | BH2: Patent_Entity_Scope | BI2: Calendar_Year_t-3 | BJ2: Calendar_Year_t-2 | BK2: Calendar_Year_t-1 | BL2: Calendar_Year_t0 | BM2: Calendar_Year_t+1 | BN2: Calendar_Year_t+2 | BO2: Calendar_Year_t+3 | BP2: Revenue_m_t-3 | BQ2: Revenue_m_t-2 | BR2: Revenue_m_t-1 | BS2: Revenue_m_t0 | BT2: Revenue_m_t+1 | BU2: Revenue_m_t+2 | BV2: Revenue_m_t+3 | BW2: Operating_Income_m_t-3 | BX2: Operating_Income_m_t-2 | BY2: Operating_Income_m_t-1 | BZ2: Operating_Income_m_t0 | CA2: Operating_Income_m_t+1 | CB2: Operating_Income_m_t+2 | CC2: Operating_Income_m_t+3 | CD2: Net_Income_m_t-3 | CE2: Net_Income_m_t-2 | CF2: Net_Income_m_t-1 | CG2: Net_Income_m_t0 | CH2: Net_Income_m_t+1 | CI2: Net_Income_m_t+2 | CJ2: Net_Income_m_t+3 | CK2: Total_Assets_m_t-3 | CL2: Total_Assets_m_t-2 | CM2: Total_Assets_m_t-1 | CN2: Total_Assets_m_t0 | CO2: Total_Assets_m_t+1 | CP2: Total_Assets_m_t+2 | CQ2: Total_Assets_m_t+3 | CR2: Total_Debt_m_t-3 | CS2: Total_Debt_m_t-2 | CT2: Total_Debt_m_t-1 | CU2: Total_Debt_m_t0 | CV2: Total_Debt_m_t+1 | CW2: Total_Debt_m_t+2 | CX2: Total_Debt_m_t+3 | CY2: R_and_D_Expense_m_t-3 | CZ2: R_and_D_Expense_m_t-2 | DA2: R_and_D_Expense_m_t-1 | DB2: R_and_D_Expense_m_t0 | DC2: R_and_D_Expense_m_t+1 | DD2: R_and_D_Expense_m_t+2 | DE2: R_and_D_Expense_m_t+3 | DF2: ROA_pct_t-3 | DG2: ROA_pct_t-2 | DH2: ROA_pct_t-1 | DI2: ROA_pct_t0 | DJ2: ROA_pct_t+1 | DK2: ROA_pct_t+2 | DL2: ROA_pct_t+3 | DM2: Operating_Margin_pct_t-3 | DN2: Operating_Margin_pct_t-2 | DO2: Operating_Margin_pct_t-1 | DP2: Operating_Margin_pct_t0 | DQ2: Operating_Margin_pct_t+1 | DR2: Operating_Margin_pct_t+2 | DS2: Operating_Margin_pct_t+3 | DT2: Leverage_pct_t-3 | DU2: Leverage_pct_t-2 | DV2: Leverage_pct_t-1 | DW2: Leverage_pct_t0 | DX2: Leverage_pct_t+1 | DY2: Leverage_pct_t+2 | DZ2: Leverage_pct_t+3 | EA2: Patent_Family_Count_t-3 | EB2: Patent_Family_Count_t-2 | EC2: Patent_Family_Count_t-1 | ED2: Patent_Family_Count_t0 | EE2: Patent_Family_Count_t+1 | EF2: Patent_Family_Count_t+2 | EG2: Patent_Family_Count_t+3 | EH2: Citation_Weighted_Output_t-3 | EI2: Citation_Weighted_Output_t-2 | EJ2: Citation_Weighted_Output_t-1 | EK2: Citation_Weighted_Output_t0 | EL2: Citation_Weighted_Output_t+1 | EM2: Citation_Weighted_Output_t+2 | EN2: Citation_Weighted_Output_t+3 | EO2: Acquirer_PreDeal_Patent_Stock | EP2: Target_PreDeal_Patent_Stock | EQ2: Relative_Knowledge_Base_Size | ER2: Technological_Relatedness_Cosine | ES2: Inventor_Location_Available | ET2: Cross_Border_Relocation_Testable | EU2: Pre_Avg_ROA | EV2: Post_Avg_ROA | EW2: Delta_ROA | EX2: Pre_Avg_Operating_Margin | EY2: Post_Avg_Operating_Margin | EZ2: Delta_Operating_Margin | FA2: Pre_Avg_Patent_Families | FB2: Post_Avg_Patent_Families | FC2: Delta_Patent_Families | FD2: Pre_Avg_Citation_Weighted | FE2: Post_Avg_Citation_Weighted | FF2: Delta_Citation_Weighted | FG2: Complete_Financial_Window | FH2: Complete_Patent_Window | FI2: Data_Ready_Flag
A3: CTL-0001 | B3: 12 | C3: Candidate alternative-rationale group | D3: 0 | E3: DATA non-innovation deals.xlsx | F3: emmes acquires neox | G3: No | H3: No | I3: No | J3: 1 | K3: Not started | L3: Eligible - 100% | M3: Review | O3: 44195 | P3: 44195 | Q3: 2020 | R3: Q4 2020 | S3: Completed | T3: Emmes Acquires Neox | U3: Mergers & Acquisitions | V3: Acquisition | W3: 100% Acquisition | X3: Czech Republic | Y3: 100% Acquisition | AB3: Emmes Corp | AC3: emmes | AD3: Neox sro | AE3: neox sro | AG3: n/a | AH3: The Emmes Corp, a contract research organization, has acquired Neox sro, a contract research organization. The transaction will allow to expand its biopharma effort and international presence. | AI3: The transaction will allow to expand its biopharma effort and international presence. | AL3: Unknown | AM3: Unknown | AS3: Emmes Corp | AT3: Neox sro | AU3: Not reviewed | AV3: Not assessed | AW3: Unknown | AX3: Unknown | AY3: Unknown | AZ3: Unknown | BA3: Unknown | BB3: Unknown | BF3: Not collected | BG3: Not collected | BH3: Not defined | BI3: =IF($Q3="","",$Q3-3) -> 2017 | BJ3: =IF($Q3="","",$Q3-2) -> 2018 | BK3: =IF($Q3="","",$Q3-1) -> 2019 | BL3: =IF($Q3="","",$Q3+0) -> 2020 | BM3: =IF($Q3="","",$Q3+1) -> 2021 | BN3: =IF($Q3="","",$Q3+2) -> 2022 | BO3: =IF($Q3="","",$Q3+3) -> 2023 | EQ3: =IF(OR($EO3="",$EP3="",$EO3=0),"",$EP3/$EO3) | ES3: Unknown | ET3: Unknown | EU3: =IF(COUNT($DF3,$DG3,$DH3)=0,"",AVERAGE($DF3,$DG3,$DH3)) | EV3: =IF(COUNT($DJ3,$DK3,$DL3)=0,"",AVERAGE($DJ3,$DK3,$DL3)) | EW3: =IF(OR($EU3="",$EV3=""),"",$EV3-$EU3) | EX3: =IF(COUNT($DM3,$DN3,$DO3)=0,"",AVERAGE($DM3,$DN3,$DO3)) | EY3: =IF(COUNT($DQ3,$DR3,$DS3)=0,"",AVERAGE($DQ3,$DR3,$DS3)) | EZ3: =IF(OR($EX3="",$EY3=""),"",$EY3-$EX3) | FA3: =IF(COUNT($EA3,$EB3,$EC3)=0,"",AVERAGE($EA3,$EB3,$EC3)) | FB3: =IF(COUNT($EE3,$EF3,$EG3)=0,"",AVERAGE($EE3,$EF3,$EG3)) | FC3: =IF(OR($FA3="",$FB3=""),"",$FB3-$FA3) | FD3: =IF(COUNT($EH3,$EI3,$EJ3)=0,"",AVERAGE($EH3,$EI3,$EJ3)) | FE3: =IF(COUNT($EL3,$EM3,$EN3)=0,"",AVERAGE($EL3,$EM3,$EN3)) | FF3: =IF(OR($FD3="",$FE3=""),"",$FE3-$FD3) | FG3: =IF(COUNT($DF3,$DG3,$DH3,$DJ3,$DK3,$DL3,$DM3,$DN3,$DO3,$DQ3,$DR3,$DS3)=12,"Yes","No") -> No | FH3: =IF(COUNT($EA3,$EB3,$EC3,$EE3,$EF3,$EG3,$EH3,$EI3,$EJ3,$EL3,$EM3,$EN3)=12,"Yes","No") -> No | FI3: =IF(AND($M3="Include",OR($FG3="Yes",$FH3="Yes")),"Ready","Not ready") -> Not ready
A4: CTL-0002 | B4: 13 | C4: Candidate alternative-rationale group | D4: 0 | E4: DATA non-innovation deals.xlsx | F4: veraxa biotech acquires araxa biosciences and velabs therapeutics | G4: No | H4: No | I4: No | J4: 1 | K4: Not started | L4: Eligible - 100% | M4: Review | O4: 44188 | P4: 44188 | Q4: 2020 | R4: Q4 2020 | S4: Completed | T4: Veraxa Biotech Acquires Araxa Biosciences and Velabs Therapeutics | U4: Mergers & Acquisitions | V4: Acquisition | W4: 100% Acquisition | X4: Germany | Y4: 100% Acquisition | AB4: VERAXA Biotech GmbH | AC4: veraxa biotech | AD4: Velabs Therapeutics GmbH (Inactive); Araxa Biosciences GmbH (Inactive) | AE4: velabs therapeutics araxa biosciences | AG4: n/a | AH4: VERAXA Biotech GmbH, a company that identifies and develops functional therapeutic antibodies and antibody-drug conjugates (ADCs) for the bio and pharmaceutical industries, has acquired life science company Araxa Biosciences GmbH and Velabs Therapeutics GmbH from Xlife Sciences. In 2021, Araxa Biosciences GmbH and Velabs Therapeutics GmbH merged to become Veraxa Biotech GmbH, which is fully owned by the Swiss entity Veraxa Biotech AG. Veraxa Biotech AG operates through Veraxa Biotech GmbH. With the acquisition of Araxa Biosciences GmbH and Velabs Therapeutics GmbH (merged into Veraxa GmbH) Veraxa Biotech AG combines two technologies with the goal to solve major challenges in antibody drug development in the fields of screening for functional therapeutic antibodies and aims to develop one of the next generation antibody drug conjugation (antibody-drug conjugates, " ADCs ") technologies to expand its preclinical antibody capacities from early screening to later stage antibody engineering and to sharpen its profile in personalized medicine and precision oncology. | AI4: The transaction will allow Veraxa Biotech to positioned as a leading provider in the identification and development of functional antibodies and drug conjugates. | AL4: Unknown | AM4: Unknown | AS4: VERAXA Biotech GmbH | AT4: Velabs Therapeutics GmbH (Inactive); Araxa Biosciences GmbH (Inactive) | AU4: Not reviewed | AV4: Not assessed | AW4: Unknown | AX4: Unknown | AY4: Unknown | AZ4: Unknown | BA4: Unknown | BB4: Unknown | BF4: Not collected | BG4: Not collected | BH4: Not defined | BI4: =IF($Q4="","",$Q4-3) -> 2017 | BJ4: =IF($Q4="","",$Q4-2) -> 2018 | BK4: =IF($Q4="","",$Q4-1) -> 2019 | BL4: =IF($Q4="","",$Q4+0) -> 2020 | BM4: =IF($Q4="","",$Q4+1) -> 2021 | BN4: =IF($Q4="","",$Q4+2) -> 2022 | BO4: =IF($Q4="","",$Q4+3) -> 2023 | EQ4: =IF(OR($EO4="",$EP4="",$EO4=0),"",$EP4/$EO4) | ES4: Unknown | ET4: Unknown | EU4: =IF(COUNT($DF4,$DG4,$DH4)=0,"",AVERAGE($DF4,$DG4,$DH4)) | EV4: =IF(COUNT($DJ4,$DK4,$DL4)=0,"",AVERAGE($DJ4,$DK4,$DL4)) | EW4: =IF(OR($EU4="",$EV4=""),"",$EV4-$EU4) | EX4: =IF(COUNT($DM4,$DN4,$DO4)=0,"",AVERAGE($DM4,$DN4,$DO4)) | EY4: =IF(COUNT($DQ4,$DR4,$DS4)=0,"",AVERAGE($DQ4,$DR4,$DS4)) | EZ4: =IF(OR($EX4="",$EY4=""),"",$EY4-$EX4) | FA4: =IF(COUNT($EA4,$EB4,$EC4)=0,"",AVERAGE($EA4,$EB4,$EC4)) | FB4: =IF(COUNT($EE4,$EF4,$EG4)=0,"",AVERAGE($EE4,$EF4,$EG4)) | FC4: =IF(OR($FA4="",$FB4=""),"",$FB4-$FA4) | FD4: =IF(COUNT($EH4,$EI4,$EJ4)=0,"",AVERAGE($EH4,$EI4,$EJ4)) | FE4: =IF(COUNT($EL4,$EM4,$EN4)=0,"",AVERAGE($EL4,$EM4,$EN4)) | FF4: =IF(OR($FD4="",$FE4=""),"",$FE4-$FD4) | FG4: =IF(COUNT($DF4,$DG4,$DH4,$DJ4,$DK4,$DL4,$DM4,$DN4,$DO4,$DQ4,$DR4,$DS4)=12,"Yes","No") -> No | FH4: =IF(COUNT($EA4,$EB4,$EC4,$EE4,$EF4,$EG4,$EH4,$EI4,$EJ4,$EL4,$EM4,$EN4)=12,"Yes","No") -> No | FI4: =IF(AND($M4="Include",OR($FG4="Yes",$FH4="Yes")),"Ready","Not ready") -> Not ready
A5: CTL-0003 | B5: 14 | C5: Candidate alternative-rationale group | D5: 0 | E5: DATA non-innovation deals.xlsx | F5: link medical research acquires irw consulting | G5: No | H5: No | I5: No | J5: 1 | K5: Not started | L5: Eligible - 100% | M5: Review | O5: 44169 | P5: 44169 | Q5: 2020 | R5: Q4 2020 | S5: Completed | T5: Link Medical Research Acquires IRW Consulting | U5: Mergers & Acquisitions | V5: Acquisition | W5: 100% Acquisition | X5: Sweden | Y5: 100% Acquisition | AB5: Link Medical Research AS | AC5: link medical research | AD5: IRW Consulting AB | AE5: irw consulting ab | AG5: n/a | AH5: Link Medical Research AS, a full-service contract research organization (CRO) providing product development services for the pharmaceutical and medical device industries, has acquired IRW Consulting AB, a clinical research organization. With this acquisition LINK Medical will continue growing and strengthening its position in the Nordics while improving its already strong offerings and increasing its clinical operations capabilities in the region. | AI5: The transaction enables LINK Medical to continue growing and strengthen its position in the Nordics while improving its already strong offerings and increasing its clinical operations capabilities in the region. | AL5: Unknown | AM5: Unknown | AS5: Link Medical Research AS | AT5: IRW Consulting AB | AU5: Not reviewed | AV5: Not assessed | AW5: Unknown | AX5: Unknown | AY5: Unknown | AZ5: Unknown | BA5: Unknown | BB5: Unknown | BF5: Not collected | BG5: Not collected | BH5: Not defined | BI5: =IF($Q5="","",$Q5-3) -> 2017 | BJ5: =IF($Q5="","",$Q5-2) -> 2018 | BK5: =IF($Q5="","",$Q5-1) -> 2019 | BL5: =IF($Q5="","",$Q5+0) -> 2020 | BM5: =IF($Q5="","",$Q5+1) -> 2021 | BN5: =IF($Q5="","",$Q5+2) -> 2022 | BO5: =IF($Q5="","",$Q5+3) -> 2023 | EQ5: =IF(OR($EO5="",$EP5="",$EO5=0),"",$EP5/$EO5) | ES5: Unknown | ET5: Unknown | EU5: =IF(COUNT($DF5,$DG5,$DH5)=0,"",AVERAGE($DF5,$DG5,$DH5)) | EV5: =IF(COUNT($DJ5,$DK5,$DL5)=0,"",AVERAGE($DJ5,$DK5,$DL5)) | EW5: =IF(OR($EU5="",$EV5=""),"",$EV5-$EU5) | EX5: =IF(COUNT($DM5,$DN5,$DO5)=0,"",AVERAGE($DM5,$DN5,$DO5)) | EY5: =IF(COUNT($DQ5,$DR5,$DS5)=0,"",AVERAGE($DQ5,$DR5,$DS5)) | EZ5: =IF(OR($EX5="",$EY5=""),"",$EY5-$EX5) | FA5: =IF(COUNT($EA5,$EB5,$EC5)=0,"",AVERAGE($EA5,$EB5,$EC5)) | FB5: =IF(COUNT($EE5,$EF5,$EG5)=0,"",AVERAGE($EE5,$EF5,$EG5)) | FC5: =IF(OR($FA5="",$FB5=""),"",$FB5-$FA5) | FD5: =IF(COUNT($EH5,$EI5,$EJ5)=0,"",AVERAGE($EH5,$EI5,$EJ5)) | FE5: =IF(COUNT($EL5,$EM5,$EN5)=0,"",AVERAGE($EL5,$EM5,$EN5)) | FF5: =IF(OR($FD5="",$FE5=""),"",$FE5-$FD5) | FG5: =IF(COUNT($DF5,$DG5,$DH5,$DJ5,$DK5,$DL5,$DM5,$DN5,$DO5,$DQ5,$DR5,$DS5)=12,"Yes","No") -> No | FH5: =IF(COUNT($EA5,$EB5,$EC5,$EE5,$EF5,$EG5,$EH5,$EI5,$EJ5,$EL5,$EM5,$EN5)=12,"Yes","No") -> No | FI5: =IF(AND($M5="Include",OR($FG5="Yes",$FH5="Yes")),"Ready","Not ready") -> Not ready
A6: CTL-0004 | B6: 15 | C6: Candidate alternative-rationale group | D6: 0 | E6: DATA non-innovation deals.xlsx | F6: immunicum acquire dcprime | G6: No | H6: No | I6: No | J6: 1 | K6: Not started | L6: Eligible - 100% | M6: Review | O6: 44153 | P6: 44186 | Q6: 2020 | R6: Q4 2020 | S6: Completed | T6: Immunicum Acquire DCprime | U6: Mergers & Acquisitions | V6: Acquisition | W6: 100% Acquisition | X6: The Netherlands | Y6: 100% Acquisition | Z6: Erik Penser Bankaktiebolag , Advokatfirman Cederquist KB , Kempen & Co NV | AA6: Allen Overy Shearman Sterling LLP , Advokatfirman Delphi AB | AB6: Mendus AB | AC6: mendus ab | AD6: DC Prime BV | AE6: dc prime | AG6: n/a | AH6: Immunicum AB, a developer of therapeutic cancer vaccines, has completed the acquisition of the shares in DCprime BV, a clinical stage biotechnology company developing cancer relapse vaccines aimed to reduce tumor recurrence, from Van Herk Investments B.V., a private equity firm. Further, prior to the closing of the transaction, Van Herk will acquire the minority shareholders’ shares in DCprime and such minority shareholders will consequently partly be paid in cash and partly in Immunicum shares. As a result of the Transaction, Van Herk will be the largest shareholder in Immunicum, holding approximately 43% of the total outstanding shares after the transaction. Customary lock-up provisions covering a period of twelve months have been put in place between Immunicum, Van Herk and DCprime minority shareholders receiving issued shares. The purchase price for all outstanding shares in DCprime will be paid through the issuance of 73,909,635 shares (Consideration Shares) in Immunicum, representing a dilution of 44.48% (44% on a fully diluted basis considering outstanding warrants). Based on the closing price of Immunicum’s shares on November 17, 2020, SEK 8.10, the consideration for the capital contributed in-kind corresponds to a total of SEK 598,668,043.50. Through issuance of the Consideration Shares, the number of shares in Immunicum will increase to a total of 166,167,166. The share capital will increase by SEK 3,695,481.75, from SEK 4,612,876.55 to a total of SEK 8,308,358.3. The dilution has been calculated as the number of issued new shares, divided by the total number of shares following the new issue. The issuance of the shares is subject to approval by an Extraordinary General Meeting (EGM) to be held on December 18, 2020. The newly combined company will maintain its corporate headquarters in Stockholm, Sweden and consolidate research, process development and future manufacturing efforts at the location in Leiden, the Netherlands. Immunicum’s shares will continue to trade on the Nasdaq Stockholm. The transaction will allow Immunicum to further build and strengthen its position as a leader in cell-based cancer immunotherapies. Pursuant to the transaction, Erik Manting, Ph.D., currently CEO of DCprime, will join Immunicum’s leadership team as Chief Business Officer and deputy CEO. Jeroen Rovers, MD, Ph.D., currently Chief Medical Officer at DCprime, will have the role of the Managing Director of DCprime in the combination. Erik Penser Bankaktiebolag is acting as financial advisor, Asperion is acting as strategic advisor and Advokatfirman Delphi AB is acting as legal advisor to Immunicum. Kempen & Co is acting as financial advisor, while Advokatfirman Cederquist KB and Allen & Overy LLP are acting as legal advisor to DCprime. Deal History: Announced: On November 11, 2020, Immunicum entered into an agreement to acquire all of the shares in DCprime from Van Herk Investments. | AI6: The transaction will allow Immunicum to further build and strengthen its position as a leader in cell-based cancer immunotherapies. | AL6: Unknown | AM6: Unknown | AS6: Mendus AB | AT6: DC Prime BV | AU6: Not reviewed | AV6: Not assessed | AW6: Unknown | AX6: Unknown | AY6: Unknown | AZ6: Unknown | BA6: Unknown | BB6: Unknown | BF6: Not collected | BG6: Not collected | BH6: Not defined | BI6: =IF($Q6="","",$Q6-3) -> 2017 | BJ6: =IF($Q6="","",$Q6-2) -> 2018 | BK6: =IF($Q6="","",$Q6-1) -> 2019 | BL6: =IF($Q6="","",$Q6+0) -> 2020 | BM6: =IF($Q6="","",$Q6+1) -> 2021 | BN6: =IF($Q6="","",$Q6+2) -> 2022 | BO6: =IF($Q6="","",$Q6+3) -> 2023 | EQ6: =IF(OR($EO6="",$EP6="",$EO6=0),"",$EP6/$EO6) | ES6: Unknown | ET6: Unknown | EU6: =IF(COUNT($DF6,$DG6,$DH6)=0,"",AVERAGE($DF6,$DG6,$DH6)) | EV6: =IF(COUNT($DJ6,$DK6,$DL6)=0,"",AVERAGE($DJ6,$DK6,$DL6)) | EW6: =IF(OR($EU6="",$EV6=""),"",$EV6-$EU6) | EX6: =IF(COUNT($DM6,$DN6,$DO6)=0,"",AVERAGE($DM6,$DN6,$DO6)) | EY6: =IF(COUNT($DQ6,$DR6,$DS6)=0,"",AVERAGE($DQ6,$DR6,$DS6)) | EZ6: =IF(OR($EX6="",$EY6=""),"",$EY6-$EX6) | FA6: =IF(COUNT($EA6,$EB6,$EC6)=0,"",AVERAGE($EA6,$EB6,$EC6)) | FB6: =IF(COUNT($EE6,$EF6,$EG6)=0,"",AVERAGE($EE6,$EF6,$EG6)) | FC6: =IF(OR($FA6="",$FB6=""),"",$FB6-$FA6) | FD6: =IF(COUNT($EH6,$EI6,$EJ6)=0,"",AVERAGE($EH6,$EI6,$EJ6)) | FE6: =IF(COUNT($EL6,$EM6,$EN6)=0,"",AVERAGE($EL6,$EM6,$EN6)) | FF6: =IF(OR($FD6="",$FE6=""),"",$FE6-$FD6) | FG6: =IF(COUNT($DF6,$DG6,$DH6,$DJ6,$DK6,$DL6,$DM6,$DN6,$DO6,$DQ6,$DR6,$DS6)=12,"Yes","No") -> No | FH6: =IF(COUNT($EA6,$EB6,$EC6,$EE6,$EF6,$EG6,$EH6,$EI6,$EJ6,$EL6,$EM6,$EN6)=12,"Yes","No") -> No | FI6: =IF(AND($M6="Include",OR($FG6="Yes",$FH6="Yes")),"Ready","Not ready") -> Not ready
A7: CTL-0005 | B7: 16 | C7: Candidate alternative-rationale group | D7: 0 | E7: DATA non-innovation deals.xlsx | F7: ucb acquires handl therapeutics | G7: No | H7: No | I7: No | J7: 1 | K7: Not started | L7: Eligible - 100% | M7: Review | O7: 44147 | P7: 44147 | Q7: 2020 | R7: Q4 2020 | S7: Completed | T7: UCB Acquires Handl Therapeutics | U7: Mergers & Acquisitions | V7: Acquisition | W7: 100% Acquisition | X7: Belgium | Y7: 100% Acquisition | AB7: UCB SA | AC7: ucb | AD7: Handl Therapeutics | AE7: handl therapeutics | AG7: n/a | AH7: UCB SA, a biopharmaceutical company, has acquired Handl Therapeutics BV, a gene therapy company. The Handl Therapeutics team will continue to be based in Leuven, Belgium, and will work very closely with UCB’s international research teams. The transaction will allow UCB to accelerate its ambition in gene therapy and strengthens its capabilities to discover and develop differentiated solutions with unique outcomes for patients. Concurrently, UCB has announced a new gene therapy research collaboration with Lacerta Therapeutics. | AI7: The transaction will allow UCB to accelerate its ambition in gene therapy and strengthens its capabilities to discover and develop differentiated solutions with unique outcomes for patients. | AL7: Unknown | AM7: Unknown | AN7: UCB BB | AS7: UCB SA | AT7: Handl Therapeutics | AU7: Not reviewed | AV7: Not assessed | AW7: Unknown | AX7: Unknown | AY7: Unknown | AZ7: Unknown | BA7: Unknown | BB7: Unknown | BE7: EUR | BF7: Complete | BG7: Complete event window — 7/7 years covered | BH7: Applicant/owner alias match for UCB Biopharma and UCB Pharma entities. | BI7: =IF($Q7="","",$Q7-3) -> 2017 | BJ7: =IF($Q7="","",$Q7-2) -> 2018 | BK7: =IF($Q7="","",$Q7-1) -> 2019 | BL7: =IF($Q7="","",$Q7+0) -> 2020 | BM7: =IF($Q7="","",$Q7+1) -> 2021 | BN7: =IF($Q7="","",$Q7+2) -> 2022 | BO7: =IF($Q7="","",$Q7+3) -> 2023 | BP7: 4530 | BQ7: 4632 | BR7: 4913 | BS7: 5347 | BT7: 5777 | BU7: 5517 | BV7: 5252 | BW7: 1130 | BX7: 1105 | BY7: 1118 | BZ7: 1093 | CA7: 1318 | CB7: 679 | CC7: 659 | CD7: 753 | CE7: 800 | CF7: 792 | CG7: 732 | CH7: 1058 | CI7: 418 | CJ7: 343 | CK7: 9917 | CL7: 10514 | CM7: 11081 | CN7: 13319 | CO7: 14210 | CP7: 15868 | CQ7: 15539 | CR7: 1630 | CS7: 1531 | CT7: 1282 | CU7: 2750 | CV7: 2141 | CW7: 3000 | CX7: 3102 | CY7: 1057 | CZ7: 1161 | DA7: 1272 | DB7: 1569 | DC7: 1629 | DD7: 1670 | DE7: 1630 | DF7: 7.4817 | DG7: 7.8312 | DH7: 7.335 | DI7: 6 | DJ7: 7.6864 | DK7: 2.7794 | DL7: 2.1842 | DM7: 24.9448 | DN7: 23.8558 | DO7: 22.756 | DP7: 20.4414 | DQ7: 22.8146 | DR7: 12.3074 | DS7: 12.5476 | DT7: 16.4364 | DU7: 14.5615 | DV7: 11.5694 | DW7: 20.6472 | DX7: 15.0669 | DY7: 18.906 | DZ7: 19.9627 | EA7: 27 | EB7: 15 | EC7: 18 | ED7: 25 | EE7: 17 | EF7: 5 | EG7: 0 | EH7: 107 | EI7: 5 | EJ7: 26 | EK7: 7 | EL7: 2 | EM7: 0 | EN7: 0 | EQ7: =IF(OR($EO7="",$EP7="",$EO7=0),"",$EP7/$EO7) | ES7: Unknown | ET7: Unknown | EU7: =IF(COUNT($DF7,$DG7,$DH7)=0,"",AVERAGE($DF7,$DG7,$DH7)) -> 7.5493 | EV7: =IF(COUNT($DJ7,$DK7,$DL7)=0,"",AVERAGE($DJ7,$DK7,$DL7)) -> 4.2166667 | EW7: =IF(OR($EU7="",$EV7=""),"",$EV7-$EU7) -> -3.3326333 | EX7: =IF(COUNT($DM7,$DN7,$DO7)=0,"",AVERAGE($DM7,$DN7,$DO7)) -> 23.8522 | EY7: =IF(COUNT($DQ7,$DR7,$DS7)=0,"",AVERAGE($DQ7,$DR7,$DS7)) -> 15.889867 | EZ7: =IF(OR($EX7="",$EY7=""),"",$EY7-$EX7) -> -7.9623333 | FA7: =IF(COUNT($EA7,$EB7,$EC7)=0,"",AVERAGE($EA7,$EB7,$EC7)) -> 20 | FB7: =IF(COUNT($EE7,$EF7,$EG7)=0,"",AVERAGE($EE7,$EF7,$EG7)) -> 7.3333333 | FC7: =IF(OR($FA7="",$FB7=""),"",$FB7-$FA7) -> -12.666667 | FD7: =IF(COUNT($EH7,$EI7,$EJ7)=0,"",AVERAGE($EH7,$EI7,$EJ7)) -> 46 | FE7: =IF(COUNT($EL7,$EM7,$EN7)=0,"",AVERAGE($EL7,$EM7,$EN7)) -> 0.66666667 | FF7: =IF(OR($FD7="",$FE7=""),"",$FE7-$FD7) -> -45.333333 | FG7: =IF(COUNT($DF7,$DG7,$DH7,$DJ7,$DK7,$DL7,$DM7,$DN7,$DO7,$DQ7,$DR7,$DS7)=12,"Yes","No") -> Yes | FH7: =IF(COUNT($EA7,$EB7,$EC7,$EE7,$EF7,$EG7,$EH7,$EI7,$EJ7,$EL7,$EM7,$EN7)=12,"Yes","No") -> Yes | FI7: =IF(AND($M7="Include",OR($FG7="Yes",$FH7="Yes")),"Ready","Not ready") -> Not ready
A8: CTL-0006 | B8: 17 | C8: Candidate alternative-rationale group | D8: 0 | E8: DATA non-innovation deals.xlsx | F8: perkinelmer acquires horizon discovery | G8: No | H8: No | I8: Yes | J8: 2 | K8: Not started | L8: Eligible - 100% | M8: Review | O8: 44137 | P8: 44188 | Q8: 2020 | R8: Q4 2020 | S8: Completed | T8: PerkinElmer Acquires Horizon Discovery | U8: Mergers & Acquisitions | V8: Acquisition | W8: 100% Acquisition | X8: United Kingdom | Y8: 100% Acquisition | Z8: Evercore Inc , Perella Weinberg Partners LP , Numis Securities Ltd | AA8: Hogan Lovells International LLP , Covington & Burling LLP | AB8: Revvity Inc | AC8: revvity | AD8: Horizon Discovery Group Ltd | AE8: horizon discovery | AF8: 383 | AG8: 383 | AH8: PerkinElmer, Inc., a provider of detection, imaging, and informatics solutions and services, has acquired Horizon Discovery Group Plc, a company engaged in the application of gene editing and gene modulation for cell line engineering, for approximately USD383 million. The transaction will allow PerkinElmer to expand its portfolio of automated life sciences discovery and applied genomics solutions to include gene editing and gene modulation tools, with future opportunities to improve cell based discovery for precision medicine. PerkinElmer UK will finance the cash consideration payable to Horizon Shareholders pursuant to the Acquisition from PerkinElmer's existing cash resources. Evercore Inc is a financial advisor, while Covington & Burling LLP is acting as legal advisor for Horizon Discovery Group. Consilium Strategic Communications Limited is acting as financial media and UK investor relations adviser to Horizon. Perella Weinberg Partners LP is acting as financial advisor, while Hogan Lovells International LLP is acting as legal advisor for PerkinElmer. Deal History: Announcement: On November 2, 2020, PerkinElmer has reached an agreement on the terms of a recommended all cash offer to acquire Horizon Discovery Group. The transaction has a total enterprise value of approximately USD368 million, is expected to close in the first quarter of 2021 subject to customary closing conditions. | AI8: The transaction will allow PerkinElmer to expand its portfolio of automated life sciences discovery and applied genomics solutions to include gene editing and gene modulation tools, with future opportunities to improve cell based discovery for precision medicine. | AL8: Unknown | AM8: Unknown | AS8: Revvity Inc | AT8: Horizon Discovery Group Ltd | AU8: Not reviewed | AV8: Not assessed | AW8: Unknown | AX8: Unknown | AY8: Unknown | AZ8: Unknown | BA8: Unknown | BB8: Unknown | BF8: Not collected | BG8: Not collected | BH8: Not defined | BI8: =IF($Q8="","",$Q8-3) -> 2017 | BJ8: =IF($Q8="","",$Q8-2) -> 2018 | BK8: =IF($Q8="","",$Q8-1) -> 2019 | BL8: =IF($Q8="","",$Q8+0) -> 2020 | BM8: =IF($Q8="","",$Q8+1) -> 2021 | BN8: =IF($Q8="","",$Q8+2) -> 2022 | BO8: =IF($Q8="","",$Q8+3) -> 2023 | EQ8: =IF(OR($EO8="",$EP8="",$EO8=0),"",$EP8/$EO8) | ES8: Unknown | ET8: Unknown | EU8: =IF(COUNT($DF8,$DG8,$DH8)=0,"",AVERAGE($DF8,$DG8,$DH8)) | EV8: =IF(COUNT($DJ8,$DK8,$DL8)=0,"",AVERAGE($DJ8,$DK8,$DL8)) | EW8: =IF(OR($EU8="",$EV8=""),"",$EV8-$EU8) | EX8: =IF(COUNT($DM8,$DN8,$DO8)=0,"",AVERAGE($DM8,$DN8,$DO8)) | EY8: =IF(COUNT($DQ8,$DR8,$DS8)=0,"",AVERAGE($DQ8,$DR8,$DS8)) | EZ8: =IF(OR($EX8="",$EY8=""),"",$EY8-$EX8) | FA8: =IF(COUNT($EA8,$EB8,$EC8)=0,"",AVERAGE($EA8,$EB8,$EC8)) | FB8: =IF(COUNT($EE8,$EF8,$EG8)=0,"",AVERAGE($EE8,$EF8,$EG8)) | FC8: =IF(OR($FA8="",$FB8=""),"",$FB8-$FA8) | FD8: =IF(COUNT($EH8,$EI8,$EJ8)=0,"",AVERAGE($EH8,$EI8,$EJ8)) | FE8: =IF(COUNT($EL8,$EM8,$EN8)=0,"",AVERAGE($EL8,$EM8,$EN8)) | FF8: =IF(OR($FD8="",$FE8=""),"",$FE8-$FD8) | FG8: =IF(COUNT($DF8,$DG8,$DH8,$DJ8,$DK8,$DL8,$DM8,$DN8,$DO8,$DQ8,$DR8,$DS8)=12,"Yes","No") -> No | FH8: =IF(COUNT($EA8,$EB8,$EC8,$EE8,$EF8,$EG8,$EH8,$EI8,$EJ8,$EL8,$EM8,$EN8)=12,"Yes","No") -> No | FI8: =IF(AND($M8="Include",OR($FG8="Yes",$FH8="Yes")),"Ready","Not ready") -> Not ready
A9: CTL-0007 | B9: 18 | C9: Candidate alternative-rationale group | D9: 0 | E9: DATA non-innovation deals.xlsx | F9: retrophin acquires orphan technologies | G9: No | H9: No | I9: No | J9: 1 | K9: Not started | L9: Eligible - 100% | M9: Review | O9: 44126 | P9: 44147 | Q9: 2020 | R9: Q4 2020 | S9: Completed | T9: Retrophin Acquires Orphan Technologies | U9: Mergers & Acquisitions | V9: Acquisition | W9: 100% Acquisition | X9: Switzerland | Y9: 100% Acquisition | Z9: Barclays Plc , Cantor Fitzgerald & Co Inc | AA9: Cooley LLP , Hogan Lovells US LLP | AB9: Travere Therapeutics Inc | AC9: travere therapeutics | AD9: Orphan Technologies Ltd | AE9: orphan technologies | AF9: 517 | AG9: 517 | AH9: Retrophin, Inc., a biopharmaceutical company, has acquired Orphan Technologies Ltd, a privately held, clinical-stage biopharmaceutical company focused on the development of product candidate OT-58 for the treatment of classical homocystinuria (HCU). Under the terms of the agreement, Retrophin will make an upfront payment of USD90 million in cash upon closing of the transaction. Orphan Technologies shareholders will also be eligible to receive up to USD427 million in additional cash payments contingent upon the achievement of key milestones in the development and commercialization of OT-58. Retrophin will also pay a tiered mid-single digit royalty on future net sales of OT-58 in the US and Europe, and potentially make a milestone payment in the event a pediatric rare disease voucher is granted. The transaction will allow Retrophin to expand pipeline of potential first-in-class therapies targeting rare diseases. Barclays Plc acted as financial advisor, while Cooley LLP acted as legal advisor to Retrophin. Cantor Fitzgerald & Co. acted as financial advisor, while Hogan Lovells US LLP acted as legal advisor to Orphan Technologies. Deal History: Announced: On October 22, 2020, Retrophin has entered into a definitive agreement to acquire Orphan Technologies. | AI9: The transaction will allow Retrophin to expand pipeline of potential first-in-class therapies targeting rare diseases. | AL9: Unknown | AM9: Unknown | AS9: Travere Therapeutics Inc | AT9: Orphan Technologies Ltd | AU9: Not reviewed | AV9: Not assessed | AW9: Unknown | AX9: Unknown | AY9: Unknown | AZ9: Unknown | BA9: Unknown | BB9: Unknown | BF9: Not collected | BG9: Not collected | BH9: Not defined | BI9: =IF($Q9="","",$Q9-3) -> 2017 | BJ9: =IF($Q9="","",$Q9-2) -> 2018 | BK9: =IF($Q9="","",$Q9-1) -> 2019 | BL9: =IF($Q9="","",$Q9+0) -> 2020 | BM9: =IF($Q9="","",$Q9+1) -> 2021 | BN9: =IF($Q9="","",$Q9+2) -> 2022 | BO9: =IF($Q9="","",$Q9+3) -> 2023 | EQ9: =IF(OR($EO9="",$EP9="",$EO9=0),"",$EP9/$EO9) | ES9: Unknown | ET9: Unknown | EU9: =IF(COUNT($DF9,$DG9,$DH9)=0,"",AVERAGE($DF9,$DG9,$DH9)) | EV9: =IF(COUNT($DJ9,$DK9,$DL9)=0,"",AVERAGE($DJ9,$DK9,$DL9)) | EW9: =IF(OR($EU9="",$EV9=""),"",$EV9-$EU9) | EX9: =IF(COUNT($DM9,$DN9,$DO9)=0,"",AVERAGE($DM9,$DN9,$DO9)) | EY9: =IF(COUNT($DQ9,$DR9,$DS9)=0,"",AVERAGE($DQ9,$DR9,$DS9)) | EZ9: =IF(OR($EX9="",$EY9=""),"",$EY9-$EX9) | FA9: =IF(COUNT($EA9,$EB9,$EC9)=0,"",AVERAGE($EA9,$EB9,$EC9)) | FB9: =IF(COUNT($EE9,$EF9,$EG9)=0,"",AVERAGE($EE9,$EF9,$EG9)) | FC9: =IF(OR($FA9="",$FB9=""),"",$FB9-$FA9) | FD9: =IF(COUNT($EH9,$EI9,$EJ9)=0,"",AVERAGE($EH9,$EI9,$EJ9)) | FE9: =IF(COUNT($EL9,$EM9,$EN9)=0,"",AVERAGE($EL9,$EM9,$EN9)) | FF9: =IF(OR($FD9="",$FE9=""),"",$FE9-$FD9) | FG9: =IF(COUNT($DF9,$DG9,$DH9,$DJ9,$DK9,$DL9,$DM9,$DN9,$DO9,$DQ9,$DR9,$DS9)=12,"Yes","No") -> No | FH9: =IF(COUNT($EA9,$EB9,$EC9,$EE9,$EF9,$EG9,$EH9,$EI9,$EJ9,$EL9,$EM9,$EN9)=12,"Yes","No") -> No | FI9: =IF(AND($M9="Include",OR($FG9="Yes",$FH9="Yes")),"Ready","Not ready") -> Not ready
A10: CTL-0008 | B10: 19 | C10: Candidate alternative-rationale group | D10: 0 | E10: DATA non-innovation deals.xlsx | F10: stada arzneimittel acquires lobsor pharma | G10: No | H10: No | I10: Yes | J10: 2 | K10: Not started | L10: Eligible - 100% | M10: Review | O10: 44106 | P10: 44106 | Q10: 2020 | R10: Q4 2020 | S10: Completed | T10: STADA Arzneimittel Acquires Lobsor Pharma | U10: Mergers & Acquisitions | V10: Acquisition | W10: 100% Acquisition | X10: Sweden | Y10: 100% Acquisition | AA10: Baker & McKenzie LLP | AB10: Stada Arzneimittel AG | AC10: stada arzneimittel | AD10: LobSor Pharmaceuticals AB | AE10: lobsor pharmaceuticals ab | AG10: n/a | AH10: STADA Arzneimittel AG, a pharmaceutical company, has acquired Lobsor Pharmaceuticals AB, a specialty pharmaceutical company focusing on innovative, proprietary technologies and drug formulations, currently for the treatment of Parkinson’s disease. By acquiring Lobsor Pharma, STADA gains rights to a triple fixed combination (levodopa, carbidopa, entacapone), delivered via modern pump technology, that has already been successfully launched in Nordic countries. The acquisition complements STADA’s portfolio and expertise in the treatment of late-stage Parkinson’s disease, where it has strong expertise via company Britannia Pharmaceuticals. This acquisition expands STADA’s specialty footprint and serves as further evidence that STADA is a go-to-partner for specialty pharmaceuticals, generics and consumer health products. Baker McKenzie acted as legal advisor to STADA for the transaction. Baker McKenzie's core deal team consists of Peder Oxhammar, Costin Mihailescu, Edvard Henriksson, Seher Budak and Maja Uppgren. | AI10: This acquisition expands STADA’s specialty footprint and serves as further evidence that STADA is a go-to-partner for specialty pharmaceuticals, generics and consumer health products. | AL10: Unknown | AM10: Unknown | AS10: Stada Arzneimittel AG | AT10: LobSor Pharmaceuticals AB | AU10: Not reviewed | AV10: Not assessed | AW10: Unknown | AX10: Unknown | AY10: Unknown | AZ10: Unknown | BA10: Unknown | BB10: Unknown | BF10: Not collected | BG10: Not collected | BH10: Not defined | BI10: =IF($Q10="","",$Q10-3) -> 2017 | BJ10: =IF($Q10="","",$Q10-2) -> 2018 | BK10: =IF($Q10="","",$Q10-1) -> 2019 | BL10: =IF($Q10="","",$Q10+0) -> 2020 | BM10: =IF($Q10="","",$Q10+1) -> 2021 | BN10: =IF($Q10="","",$Q10+2) -> 2022 | BO10: =IF($Q10="","",$Q10+3) -> 2023 | EQ10: =IF(OR($EO10="",$EP10="",$EO10=0),"",$EP10/$EO10) | ES10: Unknown | ET10: Unknown | EU10: =IF(COUNT($DF10,$DG10,$DH10)=0,"",AVERAGE($DF10,$DG10,$DH10)) | EV10: =IF(COUNT($DJ10,$DK10,$DL10)=0,"",AVERAGE($DJ10,$DK10,$DL10)) | EW10: =IF(OR($EU10="",$EV10=""),"",$EV10-$EU10) | EX10: =IF(COUNT($DM10,$DN10,$DO10)=0,"",AVERAGE($DM10,$DN10,$DO10)) | EY10: =IF(COUNT($DQ10,$DR10,$DS10)=0,"",AVERAGE($DQ10,$DR10,$DS10)) | EZ10: =IF(OR($EX10="",$EY10=""),"",$EY10-$EX10) | FA10: =IF(COUNT($EA10,$EB10,$EC10)=0,"",AVERAGE($EA10,$EB10,$EC10)) | FB10: =IF(COUNT($EE10,$EF10,$EG10)=0,"",AVERAGE($EE10,$EF10,$EG10)) | FC10: =IF(OR($FA10="",$FB10=""),"",$FB10-$FA10) | FD10: =IF(COUNT($EH10,$EI10,$EJ10)=0,"",AVERAGE($EH10,$EI10,$EJ10)) | FE10: =IF(COUNT($EL10,$EM10,$EN10)=0,"",AVERAGE($EL10,$EM10,$EN10)) | FF10: =IF(OR($FD10="",$FE10=""),"",$FE10-$FD10) | FG10: =IF(COUNT($DF10,$DG10,$DH10,$DJ10,$DK10,$DL10,$DM10,$DN10,$DO10,$DQ10,$DR10,$DS10)=12,"Yes","No") -> No | FH10: =IF(COUNT($EA10,$EB10,$EC10,$EE10,$EF10,$EG10,$EH10,$EI10,$EJ10,$EL10,$EM10,$EN10)=12,"Yes","No") -> No | FI10: =IF(AND($M10="Include",OR($FG10="Yes",$FH10="Yes")),"Ready","Not ready") -> Not ready
A11: CTL-0009 | B11: 20 | C11: Candidate alternative-rationale group | D11: 0 | E11: DATA non-innovation deals.xlsx | F11: c o c farma acquires tubilux pharma | G11: No | H11: No | I11: No | J11: 1 | K11: Not started | L11: Eligible - 100% | M11: Review | O11: 44105 | P11: 44105 | Q11: 2020 | R11: Q4 2020 | S11: Completed | T11: C.O.C. Farma Acquires Tubilux Pharma | U11: Mergers & Acquisitions | V11: Acquisition | W11: 100% Acquisition | X11: Italy | Y11: 100% Acquisition | AA11: CMS Legal Services EEIG | AB11: COC Farmaceutici Srl | AC11: coc farmaceutici | AD11: Tubilux Pharma SpA | AE11: tubilux pharma | AG11: n/a | AH11: C.O.C. Farmaceutici Srl, a contract manufacturing company, has acquired Tubilux Pharma SpA, a contract developer and manufacturer company specialising in ophthalmology. The transaction will allow both C.O.C. Farma and Tubilux Pharma to create an all-Italian CDMO in the ophthalmic field, with services, skills and technologies fully integrated; and to reinforce their ophthalmic market share, giving them a considerable competitive advantage, with promising opportunities for growth in Europe, in the M.E.N.A. market and in the US. | AI11: The transaction will allow both C.O.C. Farma and Tubilux Pharma to create an all-Italian CDMO in the ophthalmic field, with services, skills and technologies fully integrated; and to reinforce their ophthalmic market share, giving them a considerable competitive advantage, with promising opportunities for growth in Europe, in the M.E.N.A. market and in the US. | AL11: Unknown | AM11: Unknown | AS11: COC Farmaceutici Srl | AT11: Tubilux Pharma SpA | AU11: Not reviewed | AV11: Not assessed | AW11: Unknown | AX11: Unknown | AY11: Unknown | AZ11: Unknown | BA11: Unknown | BB11: Unknown | BF11: Not collected | BG11: Not collected | BH11: Not defined | BI11: =IF($Q11="","",$Q11-3) -> 2017 | BJ11: =IF($Q11="","",$Q11-2) -> 2018 | BK11: =IF($Q11="","",$Q11-1) -> 2019 | BL11: =IF($Q11="","",$Q11+0) -> 2020 | BM11: =IF($Q11="","",$Q11+1) -> 2021 | BN11: =IF($Q11="","",$Q11+2) -> 2022 | BO11: =IF($Q11="","",$Q11+3) -> 2023 | EQ11: =IF(OR($EO11="",$EP11="",$EO11=0),"",$EP11/$EO11) | ES11: Unknown | ET11: Unknown | EU11: =IF(COUNT($DF11,$DG11,$DH11)=0,"",AVERAGE($DF11,$DG11,$DH11)) | EV11: =IF(COUNT($DJ11,$DK11,$DL11)=0,"",AVERAGE($DJ11,$DK11,$DL11)) | EW11: =IF(OR($EU11="",$EV11=""),"",$EV11-$EU11) | EX11: =IF(COUNT($DM11,$DN11,$DO11)=0,"",AVERAGE($DM11,$DN11,$DO11)) | EY11: =IF(COUNT($DQ11,$DR11,$DS11)=0,"",AVERAGE($DQ11,$DR11,$DS11)) | EZ11: =IF(OR($EX11="",$EY11=""),"",$EY11-$EX11) | FA11: =IF(COUNT($EA11,$EB11,$EC11)=0,"",AVERAGE($EA11,$EB11,$EC11)) | FB11: =IF(COUNT($EE11,$EF11,$EG11)=0,"",AVERAGE($EE11,$EF11,$EG11)) | FC11: =IF(OR($FA11="",$FB11=""),"",$FB11-$FA11) | FD11: =IF(COUNT($EH11,$EI11,$EJ11)=0,"",AVERAGE($EH11,$EI11,$EJ11)) | FE11: =IF(COUNT($EL11,$EM11,$EN11)=0,"",AVERAGE($EL11,$EM11,$EN11)) | FF11: =IF(OR($FD11="",$FE11=""),"",$FE11-$FD11) | FG11: =IF(COUNT($DF11,$DG11,$DH11,$DJ11,$DK11,$DL11,$DM11,$DN11,$DO11,$DQ11,$DR11,$DS11)=12,"Yes","No") -> No | FH11: =IF(COUNT($EA11,$EB11,$EC11,$EE11,$EF11,$EG11,$EH11,$EI11,$EJ11,$EL11,$EM11,$EN11)=12,"Yes","No") -> No | FI11: =IF(AND($M11="Include",OR($FG11="Yes",$FH11="Yes")),"Ready","Not ready") -> Not ready
A12: CTL-0010 | B12: 21 | C12: Candidate alternative-rationale group | D12: 0 | E12: DATA non-innovation deals.xlsx | F12: pharmalex merges with biostat solutions | G12: No | H12: No | I12: Yes | J12: 13 | K12: Not started | L12: Review - merger | M12: Review | O12: 44103 | P12: 44103 | Q12: 2020 | R12: Q3 2020 | S12: Completed | T12: Pharmalex Merges with BioStat Solutions | U12: Mergers & Acquisitions | V12: Merger | X12: Germany , United States | AD12: BIOSTAT SOLUTIONS, INC.; PharmaLex GmbH | AE12: biostat solutions pharmalex | AG12: n/a | AH12: PharmaLex GmbH, a provider of specialized services for the pharma, biotech and medtech industries, has merged with BioStat Solutions Inc (BSSI), a company that provides business consulting services on a contract and fee basis. Following the merger with PharmaLex, Lin Li will take over management of BSSI. Ron Bromley will step down as CEO, whilst Ena Bromley will continue to provide support as non-executive director and principal consultant. | AI12: The merger with BioStat Solutions diversifies PharmaLex’s existing statistical and data science service portfolio._x000D_ _x000D_ | AL12: Unknown | AM12: Unknown | AT12: BIOSTAT SOLUTIONS, INC.; PharmaLex GmbH | AU12: Not reviewed | AV12: Not assessed | AW12: Unknown | AX12: Unknown | AY12: Unknown | AZ12: Unknown | BA12: Unknown | BB12: Unknown | BF12: Not collected | BG12: Not collected | BH12: Not defined | BI12: =IF($Q12="","",$Q12-3) -> 2017 | BJ12: =IF($Q12="","",$Q12-2) -> 2018 | BK12: =IF($Q12="","",$Q12-1) -> 2019 | BL12: =IF($Q12="","",$Q12+0) -> 2020 | BM12: =IF($Q12="","",$Q12+1) -> 2021 | BN12: =IF($Q12="","",$Q12+2) -> 2022 | BO12: =IF($Q12="","",$Q12+3) -> 2023 | EQ12: =IF(OR($EO12="",$EP12="",$EO12=0),"",$EP12/$EO12) | ES12: Unknown | ET12: Unknown | EU12: =IF(COUNT($DF12,$DG12,$DH12)=0,"",AVERAGE($DF12,$DG12,$DH12)) | EV12: =IF(COUNT($DJ12,$DK12,$DL12)=0,"",AVERAGE($DJ12,$DK12,$DL12)) | EW12: =IF(OR($EU12="",$EV12=""),"",$EV12-$EU12) | EX12: =IF(COUNT($DM12,$DN12,$DO12)=0,"",AVERAGE($DM12,$DN12,$DO12)) | EY12: =IF(COUNT($DQ12,$DR12,$DS12)=0,"",AVERAGE($DQ12,$DR12,$DS12)) | EZ12: =IF(OR($EX12="",$EY12=""),"",$EY12-$EX12) | FA12: =IF(COUNT($EA12,$EB12,$EC12)=0,"",AVERAGE($EA12,$EB12,$EC12)) | FB12: =IF(COUNT($EE12,$EF12,$EG12)=0,"",AVERAGE($EE12,$EF12,$EG12)) | FC12: =IF(OR($FA12="",$FB12=""),"",$FB12-$FA12) | FD12: =IF(COUNT($EH12,$EI12,$EJ12)=0,"",AVERAGE($EH12,$EI12,$EJ12)) | FE12: =IF(COUNT($EL12,$EM12,$EN12)=0,"",AVERAGE($EL12,$EM12,$EN12)) | FF12: =IF(OR($FD12="",$FE12=""),"",$FE12-$FD12) | FG12: =IF(COUNT($DF12,$DG12,$DH12,$DJ12,$DK12,$DL12,$DM12,$DN12,$DO12,$DQ12,$DR12,$DS12)=12,"Yes","No") -> No | FH12: =IF(COUNT($EA12,$EB12,$EC12,$EE12,$EF12,$EG12,$EH12,$EI12,$EJ12,$EL12,$EM12,$EN12)=12,"Yes","No") -> No | FI12: =IF(AND($M12="Include",OR($FG12="Yes",$FH12="Yes")),"Ready","Not ready") -> Not ready
A13: CTL-0011 | B13: 22 | C13: Candidate alternative-rationale group | D13: 0 | E13: DATA non-innovation deals.xlsx | F13: bayer acquires kandy therapeutics | G13: No | H13: No | I13: Yes | J13: 2 | K13: Not started | L13: Eligible - 100% | M13: Review | O13: 44054 | P13: 44083 | Q13: 2020 | R13: Q3 2020 | S13: Completed | T13: Bayer Acquires KaNDy Therapeutics | U13: Mergers & Acquisitions | V13: Acquisition | W13: 100% Acquisition | X13: United Kingdom | Y13: 100% Acquisition | Z13: Morgan Stanley & Co LLC , Goldman Sachs International | AA13: Linklaters LLP , Goodwin Power, LLC | AB13: Bayer AG | AC13: bayer | AD13: KaNDy Therapeutics Ltd | AE13: kandy therapeutics | AF13: 875 | AG13: 875 | AH13: Bayer AG, a life science company, has completed the acquisition KaNDy Therapeutics Ltd, a clinical-stage Women’s Health company. Under the terms of the agreement Bayer will pay an upfront consideration of USD425 million, potential milestone payments of up to USD450 million until launch followed by potential additional triple digit million sales milestone payments. The acquisition will allow Bayer to expand its drug development pipeline in women’s healthcare. Morgan Stanley acted as financial advisor to Bayer, while Linklaters acted as legal counsel. Goldman Sachs International acted as financial advisor to KaNDy Therapeutics Ltd., while Goodwin acted as legal counsel. Deal History: Announced: On August 11, 2020, Bayer agreed to acquire KaNDy Therapeutics. | AI13: The acquisition will allow Bayer to expand its drug development pipeline in women’s healthcare. | AL13: Unknown | AM13: Unknown | AS13: Bayer AG | AT13: KaNDy Therapeutics Ltd | AU13: Not reviewed | AV13: Not assessed | AW13: Unknown | AX13: Unknown | AY13: Unknown | AZ13: Unknown | BA13: Unknown | BB13: Unknown | BF13: Not collected | BG13: Not collected | BH13: Not defined | BI13: =IF($Q13="","",$Q13-3) -> 2017 | BJ13: =IF($Q13="","",$Q13-2) -> 2018 | BK13: =IF($Q13="","",$Q13-1) -> 2019 | BL13: =IF($Q13="","",$Q13+0) -> 2020 | BM13: =IF($Q13="","",$Q13+1) -> 2021 | BN13: =IF($Q13="","",$Q13+2) -> 2022 | BO13: =IF($Q13="","",$Q13+3) -> 2023 | EQ13: =IF(OR($EO13="",$EP13="",$EO13=0),"",$EP13/$EO13) | ES13: Unknown | ET13: Unknown | EU13: =IF(COUNT($DF13,$DG13,$DH13)=0,"",AVERAGE($DF13,$DG13,$DH13)) | EV13: =IF(COUNT($DJ13,$DK13,$DL13)=0,"",AVERAGE($DJ13,$DK13,$DL13)) | EW13: =IF(OR($EU13="",$EV13=""),"",$EV13-$EU13) | EX13: =IF(COUNT($DM13,$DN13,$DO13)=0,"",AVERAGE($DM13,$DN13,$DO13)) | EY13: =IF(COUNT($DQ13,$DR13,$DS13)=0,"",AVERAGE($DQ13,$DR13,$DS13)) | EZ13: =IF(OR($EX13="",$EY13=""),"",$EY13-$EX13) | FA13: =IF(COUNT($EA13,$EB13,$EC13)=0,"",AVERAGE($EA13,$EB13,$EC13)) | FB13: =IF(COUNT($EE13,$EF13,$EG13)=0,"",AVERAGE($EE13,$EF13,$EG13)) | FC13: =IF(OR($FA13="",$FB13=""),"",$FB13-$FA13) | FD13: =IF(COUNT($EH13,$EI13,$EJ13)=0,"",AVERAGE($EH13,$EI13,$EJ13)) | FE13: =IF(COUNT($EL13,$EM13,$EN13)=0,"",AVERAGE($EL13,$EM13,$EN13)) | FF13: =IF(OR($FD13="",$FE13=""),"",$FE13-$FD13) | FG13: =IF(COUNT($DF13,$DG13,$DH13,$DJ13,$DK13,$DL13,$DM13,$DN13,$DO13,$DQ13,$DR13,$DS13)=12,"Yes","No") -> No | FH13: =IF(COUNT($EA13,$EB13,$EC13,$EE13,$EF13,$EG13,$EH13,$EI13,$EJ13,$EL13,$EM13,$EN13)=12,"Yes","No") -> No | FI13: =IF(AND($M13="Include",OR($FG13="Yes",$FH13="Yes")),"Ready","Not ready") -> Not ready
A14: CTL-0012 | B14: 23 | C14: Candidate alternative-rationale group | D14: 0 | E14: DATA non-innovation deals.xlsx | F14: jr holding acquires 16 6 stake in helix immuno oncology | G14: No | H14: No | I14: No | J14: 1 | K14: Not started | L14: Exclude - minority | M14: Review | O14: 44006 | P14: 44006 | Q14: 2020 | R14: Q2 2020 | S14: Completed | T14: JR Holding Acquires 16.6% Stake in Helix Immuno-Oncology | U14: Mergers & Acquisitions | V14: Acquisition | W14: Minority Acquisition | X14: Poland | Y14: Minority Acquisition | AB14: JRH ASI SA | AC14: jrh asi | AD14: Helix Immuno-Oncology SA | AE14: helix immuno oncology | AF14: 1 | AG14: 1 | AH14: JR Holding S.A. (Operates as JR Holding Alternatywna Spolka Inwestycyjna SA) has acquired 2,200,000 series B shares, representing a 16.64% stake, in Helix Immuno-Oncology SA, a developer of innovative products based on proprietary technologies to be used in cancer immunotherapy, for gross proceeds of PLN2.97 million. As part of the transaction, JR Holding has acquired 2,200,000 series B shares at a price of PLN1.35 per share. The transaction will allow Helix Immuno-Oncology for further development and commercialization of its products. | AI14: The transaction will allow Helix Immuno-Oncology for further development and commercialization of its products. | AL14: Unknown | AM14: Unknown | AS14: JRH ASI SA | AT14: Helix Immuno-Oncology SA | AU14: Not reviewed | AV14: Not assessed | AW14: Unknown | AX14: Unknown | AY14: Unknown | AZ14: Unknown | BA14: Unknown | BB14: Unknown | BF14: Not collected | BG14: Not collected | BH14: Not defined | BI14: =IF($Q14="","",$Q14-3) -> 2017 | BJ14: =IF($Q14="","",$Q14-2) -> 2018 | BK14: =IF($Q14="","",$Q14-1) -> 2019 | BL14: =IF($Q14="","",$Q14+0) -> 2020 | BM14: =IF($Q14="","",$Q14+1) -> 2021 | BN14: =IF($Q14="","",$Q14+2) -> 2022 | BO14: =IF($Q14="","",$Q14+3) -> 2023 | EQ14: =IF(OR($EO14="",$EP14="",$EO14=0),"",$EP14/$EO14) | ES14: Unknown | ET14: Unknown | EU14: =IF(COUNT($DF14,$DG14,$DH14)=0,"",AVERAGE($DF14,$DG14,$DH14)) | EV14: =IF(COUNT($DJ14,$DK14,$DL14)=0,"",AVERAGE($DJ14,$DK14,$DL14)) | EW14: =IF(OR($EU14="",$EV14=""),"",$EV14-$EU14) | EX14: =IF(COUNT($DM14,$DN14,$DO14)=0,"",AVERAGE($DM14,$DN14,$DO14)) | EY14: =IF(COUNT($DQ14,$DR14,$DS14)=0,"",AVERAGE($DQ14,$DR14,$DS14)) | EZ14: =IF(OR($EX14="",$EY14=""),"",$EY14-$EX14) | FA14: =IF(COUNT($EA14,$EB14,$EC14)=0,"",AVERAGE($EA14,$EB14,$EC14)) | FB14: =IF(COUNT($EE14,$EF14,$EG14)=0,"",AVERAGE($EE14,$EF14,$EG14)) | FC14: =IF(OR($FA14="",$FB14=""),"",$FB14-$FA14) | FD14: =IF(COUNT($EH14,$EI14,$EJ14)=0,"",AVERAGE($EH14,$EI14,$EJ14)) | FE14: =IF(COUNT($EL14,$EM14,$EN14)=0,"",AVERAGE($EL14,$EM14,$EN14)) | FF14: =IF(OR($FD14="",$FE14=""),"",$FE14-$FD14) | FG14: =IF(COUNT($DF14,$DG14,$DH14,$DJ14,$DK14,$DL14,$DM14,$DN14,$DO14,$DQ14,$DR14,$DS14)=12,"Yes","No") -> No | FH14: =IF(COUNT($EA14,$EB14,$EC14,$EE14,$EF14,$EG14,$EH14,$EI14,$EJ14,$EL14,$EM14,$EN14)=12,"Yes","No") -> No | FI14: =IF(AND($M14="Include",OR($FG14="Yes",$FH14="Yes")),"Ready","Not ready") -> Not ready
A15: CTL-0013 | B15: 24 | C15: Candidate alternative-rationale group | D15: 0 | E15: DATA non-innovation deals.xlsx | F15: kreditanstalt fur wiederaufbau acquires 23 stake in curevac for | G15: No | H15: No | I15: No | J15: 1 | K15: Not started | L15: Exclude - minority | M15: Review | O15: 43997 | P15: 44049 | Q15: 2020 | R15: Q2 2020 | S15: Completed | T15: Kreditanstalt fur Wiederaufbau Acquires 23% Stake in CureVac for USD337.5 Million | U15: Mergers & Acquisitions | V15: Acquisition | W15: Minority Acquisition | X15: Germany | Y15: Minority Acquisition | AA15: Linklaters LLP , Rittershaus, Wissmann & von Rosenstiel GmbH | AB15: Kreditanstalt fur Wiederaufbau | AC15: kreditanstalt fur wiederaufbau | AD15: Curevac NV | AE15: curevac | AF15: 337 | AG15: 337 | AH15: The Federal Republic of Germany has invested EUR300 million (USD337.5 million) in CureVac AG, a biopharmaceutical company. The investment will be made by the Kreditanstalt fur Wiederaufbau (KfW), have been laid out in a definitive draft agreement. Under the agreement, the KfW will hold a stake of around 23% in CureVac. CureVac intends to use the proceeds for the further development of its proprietary pipeline and mRNA platform technology and the expansion of business activities. | AI15: CureVac intends to use the proceeds for the further development of its proprietary pipeline and mRNA platform technology and the expansion of business activities. | AL15: Unknown | AM15: Unknown | AS15: Kreditanstalt fur Wiederaufbau | AT15: Curevac NV | AU15: Not reviewed | AV15: Not assessed | AW15: Unknown | AX15: Unknown | AY15: Unknown | AZ15: Unknown | BA15: Unknown | BB15: Unknown | BF15: Not collected | BG15: Not collected | BH15: Not defined | BI15: =IF($Q15="","",$Q15-3) -> 2017 | BJ15: =IF($Q15="","",$Q15-2) -> 2018 | BK15: =IF($Q15="","",$Q15-1) -> 2019 | BL15: =IF($Q15="","",$Q15+0) -> 2020 | BM15: =IF($Q15="","",$Q15+1) -> 2021 | BN15: =IF($Q15="","",$Q15+2) -> 2022 | BO15: =IF($Q15="","",$Q15+3) -> 2023 | EQ15: =IF(OR($EO15="",$EP15="",$EO15=0),"",$EP15/$EO15) | ES15: Unknown | ET15: Unknown | EU15: =IF(COUNT($DF15,$DG15,$DH15)=0,"",AVERAGE($DF15,$DG15,$DH15)) | EV15: =IF(COUNT($DJ15,$DK15,$DL15)=0,"",AVERAGE($DJ15,$DK15,$DL15)) | EW15: =IF(OR($EU15="",$EV15=""),"",$EV15-$EU15) | EX15: =IF(COUNT($DM15,$DN15,$DO15)=0,"",AVERAGE($DM15,$DN15,$DO15)) | EY15: =IF(COUNT($DQ15,$DR15,$DS15)=0,"",AVERAGE($DQ15,$DR15,$DS15)) | EZ15: =IF(OR($EX15="",$EY15=""),"",$EY15-$EX15) | FA15: =IF(COUNT($EA15,$EB15,$EC15)=0,"",AVERAGE($EA15,$EB15,$EC15)) | FB15: =IF(COUNT($EE15,$EF15,$EG15)=0,"",AVERAGE($EE15,$EF15,$EG15)) | FC15: =IF(OR($FA15="",$FB15=""),"",$FB15-$FA15) | FD15: =IF(COUNT($EH15,$EI15,$EJ15)=0,"",AVERAGE($EH15,$EI15,$EJ15)) | FE15: =IF(COUNT($EL15,$EM15,$EN15)=0,"",AVERAGE($EL15,$EM15,$EN15)) | FF15: =IF(OR($FD15="",$FE15=""),"",$FE15-$FD15) | FG15: =IF(COUNT($DF15,$DG15,$DH15,$DJ15,$DK15,$DL15,$DM15,$DN15,$DO15,$DQ15,$DR15,$DS15)=12,"Yes","No") -> No | FH15: =IF(COUNT($EA15,$EB15,$EC15,$EE15,$EF15,$EG15,$EH15,$EI15,$EJ15,$EL15,$EM15,$EN15)=12,"Yes","No") -> No | FI15: =IF(AND($M15="Include",OR($FG15="Yes",$FH15="Yes")),"Ready","Not ready") -> Not ready
A16: CTL-0014 | B16: 25 | C16: Candidate alternative-rationale group | D16: 0 | E16: DATA non-innovation deals.xlsx | F16: bbi group acquires diarect | G16: No | H16: No | I16: No | J16: 1 | K16: Not started | L16: Eligible - 100% | M16: Review | O16: 43985 | P16: 43985 | Q16: 2020 | R16: Q2 2020 | S16: Completed | T16: BBI Group Acquires DIARECT | U16: Mergers & Acquisitions | V16: Acquisition | W16: 100% Acquisition | X16: Germany | Y16: 100% Acquisition | AA16: Allen Overy Shearman Sterling LLP | AB16: BBI Group Holding Ltd (Inactive) | AC16: bbi | AD16: Diarect AG | AE16: diarect | AG16: n/a | AH16: BBI Group Holding Ltd (BBI Group), a provider a portfolio of products and services through its businesses to the diagnostic, healthcare, research, defence, food and cosmetics industries, has acquired DIARECT AG, a company specializes in the development and production of recombinant and native antigens. The transaction will allow BBI Group to enhance its position as the world’s largest diagnostics components company with a market antigen portfolio. | AI16: The transaction will allow BBI Group to enhance its position as the world’s largest diagnostics components company with a market antigen portfolio. | AL16: Unknown | AM16: Unknown | AS16: BBI Group Holding Ltd (Inactive) | AT16: Diarect AG | AU16: Not reviewed | AV16: Not assessed | AW16: Unknown | AX16: Unknown | AY16: Unknown | AZ16: Unknown | BA16: Unknown | BB16: Unknown | BF16: Not collected | BG16: Not collected | BH16: Not defined | BI16: =IF($Q16="","",$Q16-3) -> 2017 | BJ16: =IF($Q16="","",$Q16-2) -> 2018 | BK16: =IF($Q16="","",$Q16-1) -> 2019 | BL16: =IF($Q16="","",$Q16+0) -> 2020 | BM16: =IF($Q16="","",$Q16+1) -> 2021 | BN16: =IF($Q16="","",$Q16+2) -> 2022 | BO16: =IF($Q16="","",$Q16+3) -> 2023 | EQ16: =IF(OR($EO16="",$EP16="",$EO16=0),"",$EP16/$EO16) | ES16: Unknown | ET16: Unknown | EU16: =IF(COUNT($DF16,$DG16,$DH16)=0,"",AVERAGE($DF16,$DG16,$DH16)) | EV16: =IF(COUNT($DJ16,$DK16,$DL16)=0,"",AVERAGE($DJ16,$DK16,$DL16)) | EW16: =IF(OR($EU16="",$EV16=""),"",$EV16-$EU16) | EX16: =IF(COUNT($DM16,$DN16,$DO16)=0,"",AVERAGE($DM16,$DN16,$DO16)) | EY16: =IF(COUNT($DQ16,$DR16,$DS16)=0,"",AVERAGE($DQ16,$DR16,$DS16)) | EZ16: =IF(OR($EX16="",$EY16=""),"",$EY16-$EX16) | FA16: =IF(COUNT($EA16,$EB16,$EC16)=0,"",AVERAGE($EA16,$EB16,$EC16)) | FB16: =IF(COUNT($EE16,$EF16,$EG16)=0,"",AVERAGE($EE16,$EF16,$EG16)) | FC16: =IF(OR($FA16="",$FB16=""),"",$FB16-$FA16) | FD16: =IF(COUNT($EH16,$EI16,$EJ16)=0,"",AVERAGE($EH16,$EI16,$EJ16)) | FE16: =IF(COUNT($EL16,$EM16,$EN16)=0,"",AVERAGE($EL16,$EM16,$EN16)) | FF16: =IF(OR($FD16="",$FE16=""),"",$FE16-$FD16) | FG16: =IF(COUNT($DF16,$DG16,$DH16,$DJ16,$DK16,$DL16,$DM16,$DN16,$DO16,$DQ16,$DR16,$DS16)=12,"Yes","No") -> No | FH16: =IF(COUNT($EA16,$EB16,$EC16,$EE16,$EF16,$EG16,$EH16,$EI16,$EJ16,$EL16,$EM16,$EN16)=12,"Yes","No") -> No | FI16: =IF(AND($M16="Include",OR($FG16="Yes",$FH16="Yes")),"Ready","Not ready") -> Not ready
A17: CTL-0015 | B17: 26 | C17: Candidate alternative-rationale group | D17: 0 | E17: DATA non-innovation deals.xlsx | F17: sygnature discovery acquires alderley oncology | G17: No | H17: No | I17: No | J17: 1 | K17: Not started | L17: Eligible - 100% | M17: Review | O17: 43985 | P17: 43985 | Q17: 2020 | R17: Q2 2020 | S17: Completed | T17: Sygnature Discovery Acquires Alderley Oncology | U17: Mergers & Acquisitions | V17: Acquisition | W17: 100% Acquisition | X17: United Kingdom | Y17: 100% Acquisition | AB17: Sygnature Discovery Ltd | AC17: sygnature discovery | AD17: Alderley Oncology | AE17: alderley oncology | AG17: n/a | AH17: Sygnature Discovery, a provider of integrated drug discovery resource and expertise, has acquired Alderley Oncology, a company focused in vivo pharmacology service provider. Until the acquisition, Alderley Oncology was run by Bruntwood SciTech, owners of Alderley Park. The acquisition will allow Sygnature Discovery to expand and enhance its drug discovery services portfolio, and further boosts its on-going investments in oncology. | AI17: The acquisition will allow Sygnature Discovery to expand and enhance its drug discovery services portfolio, and further boosts its on-going investments in oncology. | AL17: Unknown | AM17: Unknown | AS17: Sygnature Discovery Ltd | AT17: Alderley Oncology | AU17: Not reviewed | AV17: Not assessed | AW17: Unknown | AX17: Unknown | AY17: Unknown | AZ17: Unknown | BA17: Unknown | BB17: Unknown | BF17: Not collected | BG17: Not collected | BH17: Not defined | BI17: =IF($Q17="","",$Q17-3) -> 2017 | BJ17: =IF($Q17="","",$Q17-2) -> 2018 | BK17: =IF($Q17="","",$Q17-1) -> 2019 | BL17: =IF($Q17="","",$Q17+0) -> 2020 | BM17: =IF($Q17="","",$Q17+1) -> 2021 | BN17: =IF($Q17="","",$Q17+2) -> 2022 | BO17: =IF($Q17="","",$Q17+3) -> 2023 | EQ17: =IF(OR($EO17="",$EP17="",$EO17=0),"",$EP17/$EO17) | ES17: Unknown | ET17: Unknown | EU17: =IF(COUNT($DF17,$DG17,$DH17)=0,"",AVERAGE($DF17,$DG17,$DH17)) | EV17: =IF(COUNT($DJ17,$DK17,$DL17)=0,"",AVERAGE($DJ17,$DK17,$DL17)) | EW17: =IF(OR($EU17="",$EV17=""),"",$EV17-$EU17) | EX17: =IF(COUNT($DM17,$DN17,$DO17)=0,"",AVERAGE($DM17,$DN17,$DO17)) | EY17: =IF(COUNT($DQ17,$DR17,$DS17)=0,"",AVERAGE($DQ17,$DR17,$DS17)) | EZ17: =IF(OR($EX17="",$EY17=""),"",$EY17-$EX17) | FA17: =IF(COUNT($EA17,$EB17,$EC17)=0,"",AVERAGE($EA17,$EB17,$EC17)) | FB17: =IF(COUNT($EE17,$EF17,$EG17)=0,"",AVERAGE($EE17,$EF17,$EG17)) | FC17: =IF(OR($FA17="",$FB17=""),"",$FB17-$FA17) | FD17: =IF(COUNT($EH17,$EI17,$EJ17)=0,"",AVERAGE($EH17,$EI17,$EJ17)) | FE17: =IF(COUNT($EL17,$EM17,$EN17)=0,"",AVERAGE($EL17,$EM17,$EN17)) | FF17: =IF(OR($FD17="",$FE17=""),"",$FE17-$FD17) | FG17: =IF(COUNT($DF17,$DG17,$DH17,$DJ17,$DK17,$DL17,$DM17,$DN17,$DO17,$DQ17,$DR17,$DS17)=12,"Yes","No") -> No | FH17: =IF(COUNT($EA17,$EB17,$EC17,$EE17,$EF17,$EG17,$EH17,$EI17,$EJ17,$EL17,$EM17,$EN17)=12,"Yes","No") -> No | FI17: =IF(AND($M17="Include",OR($FG17="Yes",$FH17="Yes")),"Ready","Not ready") -> Not ready
A18: CTL-0016 | B18: 27 | C18: Candidate alternative-rationale group | D18: 0 | E18: DATA non-innovation deals.xlsx | F18: novavax acquires praha vaccines | G18: No | H18: No | I18: No | J18: 1 | K18: Not started | L18: Eligible - 100% | M18: Review | O18: 43978 | P18: 43978 | Q18: 2020 | R18: Q2 2020 | S18: Completed | T18: Novavax Acquires Praha Vaccines | U18: Mergers & Acquisitions | V18: Acquisition | W18: 100% Acquisition | X18: Czech Republic | Y18: 100% Acquisition | AA18: Bird & Bird LLP , Ropes & Gray LLP | AB18: Novavax Inc | AC18: novavax | AD18: Novavax CZ | AE18: novavax cz | AF18: 167 | AG18: 167 | AH18: Novavax, Inc. a late-stage biotechnology company developing next-generation vaccines for serious infectious diseases, has acquired Praha Vaccines a.s., a manufacturing unit of Cyrus Poonawalla Group, in an all cash transaction of approximately USD167 million. The acquisition includes a biologics manufacturing facility and associated assets in Bohumil, Czech Republic. The facility is expected to provide an annual capacity of over 1 billion doses of antigen starting in 2021 for NVX-CoV2373, Novavax’ COVID-19 vaccine candidate. NVX-CoV2373 consists of a stable, prefusion protein antigen made using its proprietary nanoparticle technology and includes Novavax’ proprietary Matrix-M adjuvant. The acquisition includes a 150,000-square foot state of the art vaccine and biologics manufacturing facility and other support buildings, along with the existing employees and all related and required infrastructure. The facility is completing a renovation that includes Biosafety Level-3 (BSL-3) capabilities. As part of the transaction, approximately 150 employees with significant experience in vaccine manufacturing and support have joined Novavax. The acquisition of Praha Vaccines is supported by Novavax’ funding arrangement with the Coalition for Epidemic Preparedness Innovations (CEPI), enabling Novavax to dramatically expand its manufacturing capacity. Novavax will work collaboratively with the Serum Institute of India (SII), part of the Cyrus Poonawalla Group, to increase production levels at the Bohumil facility by the end of 2020. The transaction will allow Novavax to produce 1 billion doses of its COVID-19 vaccine candidate next year. | AI18: The transaction will allow Novavax to produce 1 billion doses of its COVID-19 vaccine candidate next year. | AL18: Unknown | AM18: Unknown | AS18: Novavax Inc | AT18: Novavax CZ | AU18: Not reviewed | AV18: Not assessed | AW18: Unknown | AX18: Unknown | AY18: Unknown | AZ18: Unknown | BA18: Unknown | BB18: Unknown | BF18: Not collected | BG18: Not collected | BH18: Not defined | BI18: =IF($Q18="","",$Q18-3) -> 2017 | BJ18: =IF($Q18="","",$Q18-2) -> 2018 | BK18: =IF($Q18="","",$Q18-1) -> 2019 | BL18: =IF($Q18="","",$Q18+0) -> 2020 | BM18: =IF($Q18="","",$Q18+1) -> 2021 | BN18: =IF($Q18="","",$Q18+2) -> 2022 | BO18: =IF($Q18="","",$Q18+3) -> 2023 | EQ18: =IF(OR($EO18="",$EP18="",$EO18=0),"",$EP18/$EO18) | ES18: Unknown | ET18: Unknown | EU18: =IF(COUNT($DF18,$DG18,$DH18)=0,"",AVERAGE($DF18,$DG18,$DH18)) | EV18: =IF(COUNT($DJ18,$DK18,$DL18)=0,"",AVERAGE($DJ18,$DK18,$DL18)) | EW18: =IF(OR($EU18="",$EV18=""),"",$EV18-$EU18) | EX18: =IF(COUNT($DM18,$DN18,$DO18)=0,"",AVERAGE($DM18,$DN18,$DO18)) | EY18: =IF(COUNT($DQ18,$DR18,$DS18)=0,"",AVERAGE($DQ18,$DR18,$DS18)) | EZ18: =IF(OR($EX18="",$EY18=""),"",$EY18-$EX18) | FA18: =IF(COUNT($EA18,$EB18,$EC18)=0,"",AVERAGE($EA18,$EB18,$EC18)) | FB18: =IF(COUNT($EE18,$EF18,$EG18)=0,"",AVERAGE($EE18,$EF18,$EG18)) | FC18: =IF(OR($FA18="",$FB18=""),"",$FB18-$FA18) | FD18: =IF(COUNT($EH18,$EI18,$EJ18)=0,"",AVERAGE($EH18,$EI18,$EJ18)) | FE18: =IF(COUNT($EL18,$EM18,$EN18)=0,"",AVERAGE($EL18,$EM18,$EN18)) | FF18: =IF(OR($FD18="",$FE18=""),"",$FE18-$FD18) | FG18: =IF(COUNT($DF18,$DG18,$DH18,$DJ18,$DK18,$DL18,$DM18,$DN18,$DO18,$DQ18,$DR18,$DS18)=12,"Yes","No") -> No | FH18: =IF(COUNT($EA18,$EB18,$EC18,$EE18,$EF18,$EG18,$EH18,$EI18,$EJ18,$EL18,$EM18,$EN18)=12,"Yes","No") -> No | FI18: =IF(AND($M18="Include",OR($FG18="Yes",$FH18="Yes")),"Ready","Not ready") -> Not ready
