Workbook

Sheet Deal_Master_Wide
A1: AUDIT & ELIGIBILITY | O1: DEAL CHARACTERISTICS | AJ1: FIRM, CLASSIFICATION & SOURCE STATUS | BI1: EVENT-YEAR MAP | BP1: FINANCIAL DATA — ENTER VALUES IN REPORTED CURRENCY, MILLIONS | EA1: PATENT DATA — UNIQUE FAMILIES / CITATION-WEIGHTED OUTPUT | EO1: PATENT MODERATORS | EU1: DERIVED DiD CHECKS
A2: Deal_ID | B2: Source_Row | C2: Initial_Group | D2: Initial_Treatment_Indicator | E2: Source_File | F2: Cross_File_Key | G2: Overlap_Flag | H2: Duplicate_Flag | I2: Multiple_Deal_Acquirer | J2: Acquirer_Deal_Count_in_File | K2: Manual_Review_Status | L2: Initial_Control_Transfer_Status | M2: Main_DiD_Decision | N2: Exclusion_Reason | O2: Announced_Date | P2: Completion_Date | Q2: Completion_Year | R2: Completion_Quarter | S2: Deal_Status | T2: Deal_Headline | U2: Deal_Type_Level_1 | V2: Deal_Subtype_Level_2 | W2: Deal_Subtype_Level_3 | X2: Deal_Country_s | Y2: Deal_Subcategory | Z2: Financial_Advisors | AA2: Legal_Advisors | AB2: Acquirer_Raw | AC2: Acquirer_Normalized | AD2: Target_Raw | AE2: Target_Normalized | AF2: Deal_Value_USD_m | AG2: Deal_Value_Raw | AH2: Description | AI2: Deal_Rationale | AJ2: Acquirer_Country | AK2: Target_Country | AL2: Cross_Border_Flag | AM2: Acquirer_Listed | AN2: Bloomberg_Ticker | AO2: ISIN | AP2: LEI | AQ2: Acquirer_Parent_Mapping | AR2: Target_Parent_Mapping | AS2: Patent_Search_Acquirer_Names | AT2: Patent_Search_Target_Names | AU2: Final_Classification | AV2: Classification_Confidence | AW2: Patent_Evidence | AX2: Pipeline_Evidence | AY2: Platform_Evidence | AZ2: R_and_D_Evidence | BA2: Commercial_or_Geographic_Evidence | BB2: Mixed_Motive_Flag | BC2: Classification_Notes | BD2: Deal_Validation_Source_URL | BE2: Financial_Currency | BF2: Financial_Data_Status | BG2: Patent_Data_Status | BH2: Patent_Entity_Scope | BI2: Calendar_Year_t-3 | BJ2: Calendar_Year_t-2 | BK2: Calendar_Year_t-1 | BL2: Calendar_Year_t0 | BM2: Calendar_Year_t+1 | BN2: Calendar_Year_t+2 | BO2: Calendar_Year_t+3 | BP2: Revenue_m_t-3 | BQ2: Revenue_m_t-2 | BR2: Revenue_m_t-1 | BS2: Revenue_m_t0 | BT2: Revenue_m_t+1 | BU2: Revenue_m_t+2 | BV2: Revenue_m_t+3 | BW2: Operating_Income_m_t-3 | BX2: Operating_Income_m_t-2 | BY2: Operating_Income_m_t-1 | BZ2: Operating_Income_m_t0 | CA2: Operating_Income_m_t+1 | CB2: Operating_Income_m_t+2 | CC2: Operating_Income_m_t+3 | CD2: Net_Income_m_t-3 | CE2: Net_Income_m_t-2 | CF2: Net_Income_m_t-1 | CG2: Net_Income_m_t0 | CH2: Net_Income_m_t+1 | CI2: Net_Income_m_t+2 | CJ2: Net_Income_m_t+3 | CK2: Total_Assets_m_t-3 | CL2: Total_Assets_m_t-2 | CM2: Total_Assets_m_t-1 | CN2: Total_Assets_m_t0 | CO2: Total_Assets_m_t+1 | CP2: Total_Assets_m_t+2 | CQ2: Total_Assets_m_t+3 | CR2: Total_Debt_m_t-3 | CS2: Total_Debt_m_t-2 | CT2: Total_Debt_m_t-1 | CU2: Total_Debt_m_t0 | CV2: Total_Debt_m_t+1 | CW2: Total_Debt_m_t+2 | CX2: Total_Debt_m_t+3 | CY2: R_and_D_Expense_m_t-3 | CZ2: R_and_D_Expense_m_t-2 | DA2: R_and_D_Expense_m_t-1 | DB2: R_and_D_Expense_m_t0 | DC2: R_and_D_Expense_m_t+1 | DD2: R_and_D_Expense_m_t+2 | DE2: R_and_D_Expense_m_t+3 | DF2: ROA_pct_t-3 | DG2: ROA_pct_t-2 | DH2: ROA_pct_t-1 | DI2: ROA_pct_t0 | DJ2: ROA_pct_t+1 | DK2: ROA_pct_t+2 | DL2: ROA_pct_t+3 | DM2: Operating_Margin_pct_t-3 | DN2: Operating_Margin_pct_t-2 | DO2: Operating_Margin_pct_t-1 | DP2: Operating_Margin_pct_t0 | DQ2: Operating_Margin_pct_t+1 | DR2: Operating_Margin_pct_t+2 | DS2: Operating_Margin_pct_t+3 | DT2: Leverage_pct_t-3 | DU2: Leverage_pct_t-2 | DV2: Leverage_pct_t-1 | DW2: Leverage_pct_t0 | DX2: Leverage_pct_t+1 | DY2: Leverage_pct_t+2 | DZ2: Leverage_pct_t+3 | EA2: Patent_Family_Count_t-3 | EB2: Patent_Family_Count_t-2 | EC2: Patent_Family_Count_t-1 | ED2: Patent_Family_Count_t0 | EE2: Patent_Family_Count_t+1 | EF2: Patent_Family_Count_t+2 | EG2: Patent_Family_Count_t+3 | EH2: Citation_Weighted_Output_t-3 | EI2: Citation_Weighted_Output_t-2 | EJ2: Citation_Weighted_Output_t-1 | EK2: Citation_Weighted_Output_t0 | EL2: Citation_Weighted_Output_t+1 | EM2: Citation_Weighted_Output_t+2 | EN2: Citation_Weighted_Output_t+3 | EO2: Acquirer_PreDeal_Patent_Stock | EP2: Target_PreDeal_Patent_Stock | EQ2: Relative_Knowledge_Base_Size | ER2: Technological_Relatedness_Cosine | ES2: Inventor_Location_Available | ET2: Cross_Border_Relocation_Testable | EU2: Pre_Avg_ROA | EV2: Post_Avg_ROA | EW2: Delta_ROA | EX2: Pre_Avg_Operating_Margin | EY2: Post_Avg_Operating_Margin | EZ2: Delta_Operating_Margin | FA2: Pre_Avg_Patent_Families | FB2: Post_Avg_Patent_Families | FC2: Delta_Patent_Families | FD2: Pre_Avg_Citation_Weighted | FE2: Post_Avg_Citation_Weighted | FF2: Delta_Citation_Weighted | FG2: Complete_Financial_Window | FH2: Complete_Patent_Window | FI2: Data_Ready_Flag
A3: TRT-0001 | B3: 12 | C3: Candidate treatment group | D3: 1 | E3: DATA - Innovation driven deals.xlsx | F3: les laboratoires servier acquires symphogen | G3: Yes | H3: No | I3: No | J3: 1 | K3: Not started | L3: Eligible - 100% | M3: Review | O3: 43924 | P3: 43986 | Q3: 2020 | R3: Q2 2020 | S3: Completed | T3: Les Laboratoires Servier Acquires Symphogen | U3: Mergers & Acquisitions | V3: Acquisition | W3: 100% Acquisition | X3: Denmark | Y3: 100% Acquisition | Z3: Lazard Inc , Rothschild & Co Bank AG | AA3: Plesner , McDermott Will & Emery LLP , Perkins Coie LLP , Gorrissen Federspiel Advokatpartnerselskab | AB3: Les Laboratoires Servier SAS | AC3: les laboratoires servier | AD3: Symphogen A/S | AE3: symphogen a s | AG3: n/a | AH3: Les Laboratoires Servier SA, a pharmaceutical company, has completed the acquisition of Symphogen A/S, a therapeutic antibody discovery company. Following the transaction, Symphogen will now function as the antibody center of excellence of Servier in several different therapeutic areas including oncology. Symphogen, now a subsidiary of Servier, will keep its operational autonomy and continue to rely on its experienced employees while maintaining its headquarters in Ballerup, Denmark. As part of the acquisition, Christophe Thurieau, Executive Director of Servier Research Institute, has been appointed Chief Executive Officer of Symphogen and Karin Garre, former Chief Operating Officer of Symphogen, has been appointed General Manager of Symphogen. Martin Olin, former Chief Executive Officer of Symphogen, will act as an external consultant to support this transition. This transaction enables Servier to strengthen its R&D pipeline by acquiring antibody pipeline and next-generation antibody technologies. Lazard acted as financial advisor, while McDermott Will & Emery and Gorrissen Federspiel Advokatpartnerselskab acted as legal advisors to Servier. Rothschild & Co. acted as financial advisor and Plesner Advokatpartnerselskab and Perkins Coie LLP acted as legal advisors to Symphogen. Deal History: Announced: On April 3, 2020, Les Laboratoires Servier entered into a definitive agreement with the owners of Symphogen. | AI3: This transaction enables Servier to strengthen its R&D pipeline by acquiring antibody pipeline and next-generation antibody technologies. | AL3: Unknown | AM3: Unknown | AS3: Les Laboratoires Servier SAS | AT3: Symphogen A/S | AU3: Not reviewed | AV3: Not assessed | AW3: Unknown | AX3: Unknown | AY3: Unknown | AZ3: Unknown | BA3: Unknown | BB3: Unknown | BF3: Not collected | BG3: Not collected | BH3: Not defined | BI3: =IF($Q3="","",$Q3-3) -> 2017 | BJ3: =IF($Q3="","",$Q3-2) -> 2018 | BK3: =IF($Q3="","",$Q3-1) -> 2019 | BL3: =IF($Q3="","",$Q3+0) -> 2020 | BM3: =IF($Q3="","",$Q3+1) -> 2021 | BN3: =IF($Q3="","",$Q3+2) -> 2022 | BO3: =IF($Q3="","",$Q3+3) -> 2023 | EQ3: =IF(OR($EO3="",$EP3="",$EO3=0),"",$EP3/$EO3) | ES3: Unknown | ET3: Unknown | EU3: =IF(COUNT($DF3,$DG3,$DH3)=0,"",AVERAGE($DF3,$DG3,$DH3)) | EV3: =IF(COUNT($DJ3,$DK3,$DL3)=0,"",AVERAGE($DJ3,$DK3,$DL3)) | EW3: =IF(OR($EU3="",$EV3=""),"",$EV3-$EU3) | EX3: =IF(COUNT($DM3,$DN3,$DO3)=0,"",AVERAGE($DM3,$DN3,$DO3)) | EY3: =IF(COUNT($DQ3,$DR3,$DS3)=0,"",AVERAGE($DQ3,$DR3,$DS3)) | EZ3: =IF(OR($EX3="",$EY3=""),"",$EY3-$EX3) | FA3: =IF(COUNT($EA3,$EB3,$EC3)=0,"",AVERAGE($EA3,$EB3,$EC3)) | FB3: =IF(COUNT($EE3,$EF3,$EG3)=0,"",AVERAGE($EE3,$EF3,$EG3)) | FC3: =IF(OR($FA3="",$FB3=""),"",$FB3-$FA3) | FD3: =IF(COUNT($EH3,$EI3,$EJ3)=0,"",AVERAGE($EH3,$EI3,$EJ3)) | FE3: =IF(COUNT($EL3,$EM3,$EN3)=0,"",AVERAGE($EL3,$EM3,$EN3)) | FF3: =IF(OR($FD3="",$FE3=""),"",$FE3-$FD3) | FG3: =IF(COUNT($DF3,$DG3,$DH3,$DJ3,$DK3,$DL3,$DM3,$DN3,$DO3,$DQ3,$DR3,$DS3)=12,"Yes","No") -> No | FH3: =IF(COUNT($EA3,$EB3,$EC3,$EE3,$EF3,$EG3,$EH3,$EI3,$EJ3,$EL3,$EM3,$EN3)=12,"Yes","No") -> No | FI3: =IF(AND($M3="Include",OR($FG3="Yes",$FH3="Yes")),"Ready","Not ready") -> Not ready
A4: TRT-0002 | B4: 13 | C4: Candidate treatment group | D4: 1 | E4: DATA - Innovation driven deals.xlsx | F4: towa pharma acquires pensa investments | G4: Yes | H4: No | I4: No | J4: 1 | K4: Not started | L4: Eligible - 100% | M4: Review | O4: 43822 | P4: 43861 | Q4: 2020 | R4: Q4 2019 | S4: Completed | T4: Towa Pharma Acquires Pensa Investments | U4: Mergers & Acquisitions | V4: Acquisition | W4: 100% Acquisition | X4: Spain | Y4: 100% Acquisition | Z4: Lazard Inc , Barclays Plc | AA4: Nishimura & Asahi , Clifford Chance LLP , Gomez-Acebo & Pombo Abogados SLP | AB4: Towa Pharmaceutical Co Ltd | AC4: towa pharmaceutical | AD4: Pensa Investments, S.L. | AE4: pensa investments s l | AF4: 354 | AG4: 354 | AH4: Towa Pharmaceutical Co. Ltd., a company engaged in the manufacture and distribution of pharmaceutical products, has completed its acquisition of Pensa Investments, S.L., a company that provides affiliate pharmaceutical manufacturing facilities including pharmaceutical development, from Esteve Pharmaceuticals, S.A., a pharmaceutical company. Breckenridge Pharma announced Towa Pharma completed its acquisition of Esteve’s generics division, including Breckenridge. The purchase price of Pensa will be an all cash deal with an upfront payment of EUR320 million. The transaction will allow Towa Pharma to accelerate its overseas business presence and to provide quality and value-added generic medicines to patients in all over world. Deal History: Announced: On December 21, 2019, Towa Pharma reached an agreement to acquire 100% stake in Pensa Investments from Esteve Pharma. | AI4: The transaction will allow Towa Pharma to accelerate its overseas business presence and to provide quality and value-added generic medicines to patients in all over world. | AL4: Unknown | AM4: Unknown | AS4: Towa Pharmaceutical Co Ltd | AT4: Pensa Investments, S.L. | AU4: Not reviewed | AV4: Not assessed | AW4: Unknown | AX4: Unknown | AY4: Unknown | AZ4: Unknown | BA4: Unknown | BB4: Unknown | BF4: Not collected | BG4: Not collected | BH4: Not defined | BI4: =IF($Q4="","",$Q4-3) -> 2017 | BJ4: =IF($Q4="","",$Q4-2) -> 2018 | BK4: =IF($Q4="","",$Q4-1) -> 2019 | BL4: =IF($Q4="","",$Q4+0) -> 2020 | BM4: =IF($Q4="","",$Q4+1) -> 2021 | BN4: =IF($Q4="","",$Q4+2) -> 2022 | BO4: =IF($Q4="","",$Q4+3) -> 2023 | EQ4: =IF(OR($EO4="",$EP4="",$EO4=0),"",$EP4/$EO4) | ES4: Unknown | ET4: Unknown | EU4: =IF(COUNT($DF4,$DG4,$DH4)=0,"",AVERAGE($DF4,$DG4,$DH4)) | EV4: =IF(COUNT($DJ4,$DK4,$DL4)=0,"",AVERAGE($DJ4,$DK4,$DL4)) | EW4: =IF(OR($EU4="",$EV4=""),"",$EV4-$EU4) | EX4: =IF(COUNT($DM4,$DN4,$DO4)=0,"",AVERAGE($DM4,$DN4,$DO4)) | EY4: =IF(COUNT($DQ4,$DR4,$DS4)=0,"",AVERAGE($DQ4,$DR4,$DS4)) | EZ4: =IF(OR($EX4="",$EY4=""),"",$EY4-$EX4) | FA4: =IF(COUNT($EA4,$EB4,$EC4)=0,"",AVERAGE($EA4,$EB4,$EC4)) | FB4: =IF(COUNT($EE4,$EF4,$EG4)=0,"",AVERAGE($EE4,$EF4,$EG4)) | FC4: =IF(OR($FA4="",$FB4=""),"",$FB4-$FA4) | FD4: =IF(COUNT($EH4,$EI4,$EJ4)=0,"",AVERAGE($EH4,$EI4,$EJ4)) | FE4: =IF(COUNT($EL4,$EM4,$EN4)=0,"",AVERAGE($EL4,$EM4,$EN4)) | FF4: =IF(OR($FD4="",$FE4=""),"",$FE4-$FD4) | FG4: =IF(COUNT($DF4,$DG4,$DH4,$DJ4,$DK4,$DL4,$DM4,$DN4,$DO4,$DQ4,$DR4,$DS4)=12,"Yes","No") -> No | FH4: =IF(COUNT($EA4,$EB4,$EC4,$EE4,$EF4,$EG4,$EH4,$EI4,$EJ4,$EL4,$EM4,$EN4)=12,"Yes","No") -> No | FI4: =IF(AND($M4="Include",OR($FG4="Yes",$FH4="Yes")),"Ready","Not ready") -> Not ready
A5: TRT-0003 | B5: 14 | C5: Candidate treatment group | D5: 1 | E5: DATA - Innovation driven deals.xlsx | F5: pfizer acquires therachon for | G5: Yes | H5: No | I5: No | J5: 1 | K5: Not started | L5: Eligible - 100% | M5: Review | O5: 43593 | P5: 43647 | Q5: 2019 | R5: Q2 2019 | S5: Completed | T5: Pfizer Acquires Therachon for USD810 Million | U5: Mergers & Acquisitions | V5: Acquisition | W5: 100% Acquisition | X5: Switzerland | Y5: 100% Acquisition | Z5: The Goldman Sachs Group Inc | AA5: Cooley LLP , Homburger AG , Lenz & Staehelin , Arnold & Porter LLP | AB5: Pfizer Inc | AC5: pfizer | AD5: Therachon AG (Inactive) | AE5: therachon | AF5: 810 | AG5: 810 | AH5: Pfizer Inc., a pharmaceutical company, has completion acquisition of all the shares of Therachon Holding AG, a clinical-stage biotechnology company focused on rare diseases with assets in development for the treatment of achondroplasia and short bowel syndrome (SBS). Under the terms of the transaction, Pfizer acquired Therachon for USD340 million with an additional USD470 million in additional payments contingent on the achievement of key milestones in the development and commercialization of TA-46. TA-46 is an investigational, soluble recombinant human fibroblast growth factor receptor 3 (FGFR3) decoy, for bone development abnormalities associated with achondroplasia. Prior to the closing of the transaction with Pfizer, Therachon will spin-off its apraglutide development program into a separate, independent company. Apraglutide is a GLP-2 analog in Phase II development for short bowel syndrome. Pfizer Ventures, the venture capital arm of Pfizer Inc., currently holds a minority stake and will continue to hold an equity stake in the new company. The transaction is not expected to impact Pfizer’s current 2019 adjusted financial guidance. The acquisition enables Pfizer to expand its rare disease portfolio with potential first-in-class therapy for achondroplasia through the development of TA-46. Goldman Sachs acted as financial advisor while Cooley LLP and Homburger AG acted as legal advisors to Therachon. Arnold & Porter and Lenz & Staehelin acted as legal advisors to Pfizer. Deal History: Announced: On May 8, 2019, Pfizer entered into a definitive agreement to acquire all the shares of Therachon. | AI5: The acquisition enables Pfizer to expand its rare disease portfolio with potential first-in-class therapy for achondroplasia through the development of TA-46. | AL5: Unknown | AM5: Unknown | AS5: Pfizer Inc | AT5: Therachon AG (Inactive) | AU5: Not reviewed | AV5: Not assessed | AW5: Unknown | AX5: Unknown | AY5: Unknown | AZ5: Unknown | BA5: Unknown | BB5: Unknown | BF5: Not collected | BG5: Not collected | BH5: Not defined | BI5: =IF($Q5="","",$Q5-3) -> 2016 | BJ5: =IF($Q5="","",$Q5-2) -> 2017 | BK5: =IF($Q5="","",$Q5-1) -> 2018 | BL5: =IF($Q5="","",$Q5+0) -> 2019 | BM5: =IF($Q5="","",$Q5+1) -> 2020 | BN5: =IF($Q5="","",$Q5+2) -> 2021 | BO5: =IF($Q5="","",$Q5+3) -> 2022 | EQ5: =IF(OR($EO5="",$EP5="",$EO5=0),"",$EP5/$EO5) | ES5: Unknown | ET5: Unknown | EU5: =IF(COUNT($DF5,$DG5,$DH5)=0,"",AVERAGE($DF5,$DG5,$DH5)) | EV5: =IF(COUNT($DJ5,$DK5,$DL5)=0,"",AVERAGE($DJ5,$DK5,$DL5)) | EW5: =IF(OR($EU5="",$EV5=""),"",$EV5-$EU5) | EX5: =IF(COUNT($DM5,$DN5,$DO5)=0,"",AVERAGE($DM5,$DN5,$DO5)) | EY5: =IF(COUNT($DQ5,$DR5,$DS5)=0,"",AVERAGE($DQ5,$DR5,$DS5)) | EZ5: =IF(OR($EX5="",$EY5=""),"",$EY5-$EX5) | FA5: =IF(COUNT($EA5,$EB5,$EC5)=0,"",AVERAGE($EA5,$EB5,$EC5)) | FB5: =IF(COUNT($EE5,$EF5,$EG5)=0,"",AVERAGE($EE5,$EF5,$EG5)) | FC5: =IF(OR($FA5="",$FB5=""),"",$FB5-$FA5) | FD5: =IF(COUNT($EH5,$EI5,$EJ5)=0,"",AVERAGE($EH5,$EI5,$EJ5)) | FE5: =IF(COUNT($EL5,$EM5,$EN5)=0,"",AVERAGE($EL5,$EM5,$EN5)) | FF5: =IF(OR($FD5="",$FE5=""),"",$FE5-$FD5) | FG5: =IF(COUNT($DF5,$DG5,$DH5,$DJ5,$DK5,$DL5,$DM5,$DN5,$DO5,$DQ5,$DR5,$DS5)=12,"Yes","No") -> No | FH5: =IF(COUNT($EA5,$EB5,$EC5,$EE5,$EF5,$EG5,$EH5,$EI5,$EJ5,$EL5,$EM5,$EN5)=12,"Yes","No") -> No | FI5: =IF(AND($M5="Include",OR($FG5="Yes",$FH5="Yes")),"Ready","Not ready") -> Not ready
A6: TRT-0004 | B6: 15 | C6: Candidate treatment group | D6: 1 | E6: DATA - Innovation driven deals.xlsx | F6: gyroscope therapeutics merges with orbit biomedical | G6: Yes | H6: No | I6: No | J6: 1 | K6: Not started | L6: Review - merger | M6: Review | O6: 43566 | P6: 43566 | Q6: 2019 | R6: Q2 2019 | S6: Completed | T6: Gyroscope Therapeutics Merges with Orbit Biomedical | U6: Mergers & Acquisitions | V6: Merger | X6: United Kingdom , United States | AB6: Gyroscope Therapeutics Holdings Plc | AC6: gyroscope therapeutics | AD6: Orbit Biomedical Inc; Gyroscope Therapeutics Holdings Plc | AE6: orbit biomedical gyroscope therapeutics | AG6: n/a | AH6: Gyroscope Therapeutics Ltd, an ophthalmology company developing genetically defined therapies for retinal diseases, and Orbit Biomedical, a medical device company focused on precision sub-retinal therapeutic delivery, have merged to form a combined retinal gene therapy platform. Under the terms, Syncona Ltd, the shareholder of both the companies, will own 82% of the enlarged company, which will retain the Gyroscope name. The merger enables the companies to form a sub-retinal surgical platform with Gyroscope's clinical stage pipeline and gene therapy manufacturing platform. | AI6: The merger enables the companies to form a sub-retinal surgical platform with Gyroscope's clinical stage pipeline and gene therapy manufacturing platform. | AL6: Unknown | AM6: Unknown | AS6: Gyroscope Therapeutics Holdings Plc | AT6: Orbit Biomedical Inc; Gyroscope Therapeutics Holdings Plc | AU6: Not reviewed | AV6: Not assessed | AW6: Unknown | AX6: Unknown | AY6: Unknown | AZ6: Unknown | BA6: Unknown | BB6: Unknown | BF6: Not collected | BG6: Not collected | BH6: Not defined | BI6: =IF($Q6="","",$Q6-3) -> 2016 | BJ6: =IF($Q6="","",$Q6-2) -> 2017 | BK6: =IF($Q6="","",$Q6-1) -> 2018 | BL6: =IF($Q6="","",$Q6+0) -> 2019 | BM6: =IF($Q6="","",$Q6+1) -> 2020 | BN6: =IF($Q6="","",$Q6+2) -> 2021 | BO6: =IF($Q6="","",$Q6+3) -> 2022 | EQ6: =IF(OR($EO6="",$EP6="",$EO6=0),"",$EP6/$EO6) | ES6: Unknown | ET6: Unknown | EU6: =IF(COUNT($DF6,$DG6,$DH6)=0,"",AVERAGE($DF6,$DG6,$DH6)) | EV6: =IF(COUNT($DJ6,$DK6,$DL6)=0,"",AVERAGE($DJ6,$DK6,$DL6)) | EW6: =IF(OR($EU6="",$EV6=""),"",$EV6-$EU6) | EX6: =IF(COUNT($DM6,$DN6,$DO6)=0,"",AVERAGE($DM6,$DN6,$DO6)) | EY6: =IF(COUNT($DQ6,$DR6,$DS6)=0,"",AVERAGE($DQ6,$DR6,$DS6)) | EZ6: =IF(OR($EX6="",$EY6=""),"",$EY6-$EX6) | FA6: =IF(COUNT($EA6,$EB6,$EC6)=0,"",AVERAGE($EA6,$EB6,$EC6)) | FB6: =IF(COUNT($EE6,$EF6,$EG6)=0,"",AVERAGE($EE6,$EF6,$EG6)) | FC6: =IF(OR($FA6="",$FB6=""),"",$FB6-$FA6) | FD6: =IF(COUNT($EH6,$EI6,$EJ6)=0,"",AVERAGE($EH6,$EI6,$EJ6)) | FE6: =IF(COUNT($EL6,$EM6,$EN6)=0,"",AVERAGE($EL6,$EM6,$EN6)) | FF6: =IF(OR($FD6="",$FE6=""),"",$FE6-$FD6) | FG6: =IF(COUNT($DF6,$DG6,$DH6,$DJ6,$DK6,$DL6,$DM6,$DN6,$DO6,$DQ6,$DR6,$DS6)=12,"Yes","No") -> No | FH6: =IF(COUNT($EA6,$EB6,$EC6,$EE6,$EF6,$EG6,$EH6,$EI6,$EJ6,$EL6,$EM6,$EN6)=12,"Yes","No") -> No | FI6: =IF(AND($M6="Include",OR($FG6="Yes",$FH6="Yes")),"Ready","Not ready") -> Not ready
A7: TRT-0005 | B7: 16 | C7: Candidate treatment group | D7: 1 | E7: DATA - Innovation driven deals.xlsx | F7: trinetx acquires custodix | G7: Yes | H7: No | I7: No | J7: 1 | K7: Not started | L7: Eligible - 100% | M7: Review | O7: 43557 | P7: 43557 | Q7: 2019 | R7: Q2 2019 | S7: Completed | T7: TriNetX Acquires Custodix | U7: Mergers & Acquisitions | V7: Acquisition | W7: 100% Acquisition | X7: Belgium | Y7: 100% Acquisition | AB7: TriNetX LLC | AC7: trinetx | AD7: Custodix NV | AE7: custodix | AG7: n/a | AH7: TriNetX, Inc., a health research network, has acquired Custodix NV and its InSite network, a provider of services for clinical trial design, patient feasibility, and enabling workflow for patient recruitment. The InSite platform allows the re-use of Electronic Health Records (EHR) data for research. The acquisition enables TriNetx to provide a largest platform for clinical research to healthcare organizations throughout Europe. | AI7: The acquisition enables TriNetx to provide a largest platform for clinical research to healthcare organizations throughout Europe. | AL7: Unknown | AM7: Unknown | AS7: TriNetX LLC | AT7: Custodix NV | AU7: Not reviewed | AV7: Not assessed | AW7: Unknown | AX7: Unknown | AY7: Unknown | AZ7: Unknown | BA7: Unknown | BB7: Unknown | BF7: Not collected | BG7: Not collected | BH7: Not defined | BI7: =IF($Q7="","",$Q7-3) -> 2016 | BJ7: =IF($Q7="","",$Q7-2) -> 2017 | BK7: =IF($Q7="","",$Q7-1) -> 2018 | BL7: =IF($Q7="","",$Q7+0) -> 2019 | BM7: =IF($Q7="","",$Q7+1) -> 2020 | BN7: =IF($Q7="","",$Q7+2) -> 2021 | BO7: =IF($Q7="","",$Q7+3) -> 2022 | EQ7: =IF(OR($EO7="",$EP7="",$EO7=0),"",$EP7/$EO7) | ES7: Unknown | ET7: Unknown | EU7: =IF(COUNT($DF7,$DG7,$DH7)=0,"",AVERAGE($DF7,$DG7,$DH7)) | EV7: =IF(COUNT($DJ7,$DK7,$DL7)=0,"",AVERAGE($DJ7,$DK7,$DL7)) | EW7: =IF(OR($EU7="",$EV7=""),"",$EV7-$EU7) | EX7: =IF(COUNT($DM7,$DN7,$DO7)=0,"",AVERAGE($DM7,$DN7,$DO7)) | EY7: =IF(COUNT($DQ7,$DR7,$DS7)=0,"",AVERAGE($DQ7,$DR7,$DS7)) | EZ7: =IF(OR($EX7="",$EY7=""),"",$EY7-$EX7) | FA7: =IF(COUNT($EA7,$EB7,$EC7)=0,"",AVERAGE($EA7,$EB7,$EC7)) | FB7: =IF(COUNT($EE7,$EF7,$EG7)=0,"",AVERAGE($EE7,$EF7,$EG7)) | FC7: =IF(OR($FA7="",$FB7=""),"",$FB7-$FA7) | FD7: =IF(COUNT($EH7,$EI7,$EJ7)=0,"",AVERAGE($EH7,$EI7,$EJ7)) | FE7: =IF(COUNT($EL7,$EM7,$EN7)=0,"",AVERAGE($EL7,$EM7,$EN7)) | FF7: =IF(OR($FD7="",$FE7=""),"",$FE7-$FD7) | FG7: =IF(COUNT($DF7,$DG7,$DH7,$DJ7,$DK7,$DL7,$DM7,$DN7,$DO7,$DQ7,$DR7,$DS7)=12,"Yes","No") -> No | FH7: =IF(COUNT($EA7,$EB7,$EC7,$EE7,$EF7,$EG7,$EH7,$EI7,$EJ7,$EL7,$EM7,$EN7)=12,"Yes","No") -> No | FI7: =IF(AND($M7="Include",OR($FG7="Yes",$FH7="Yes")),"Ready","Not ready") -> Not ready
A8: TRT-0006 | B8: 17 | C8: Candidate treatment group | D8: 1 | E8: DATA - Innovation driven deals.xlsx | F8: bravo bidco boston scientific acquires btg for | G8: Yes | H8: No | I8: No | J8: 1 | K8: Not started | L8: Eligible - 100% | M8: Review | O8: 43424 | P8: 43696 | Q8: 2019 | R8: Q4 2018 | S8: Completed | T8: Bravo Bidco (Boston Scientific) Acquires BTG for USD4.24 Billion | U8: Mergers & Acquisitions | V8: Acquisition | W8: 100% Acquisition | X8: United Kingdom | Y8: 100% Acquisition | Z8: Rothschild & Co SCA , The Goldman Sachs Group Inc , Deutsche Bank AG , J.P. Morgan Cazenove Ltd (Inactive) , Barclays Wealth Management , Goldman Sachs International | AA8: Shearman & Sterling LLP , Simpson Thacher & Bartlett LLP , Allen Overy Shearman Sterling LLP , Travers Smith LLP , White & Case LLP , Arnold & Porter Kaye Scholer LLP | AB8: Bravo Bidco Ltd | AC8: bravo bidco | AD8: BTG Ltd | AE8: btg | AF8: 4239 | AG8: 4239 | AH8: Boston Scientific Corp, a medical technology, through its wholly-owned subsidiary, Bravo Bidco Ltd, has completed the acquisition of BTG plc, a company which develops and commercializes products used in minimally-invasive procedures targeting cancer and vascular diseases, as well as acute care pharmaceuticals, for GBP3.3 billion. In addition to the Interventional Medicine product lines, the BTG portfolio also includes a specialty pharmaceutical business comprised of acute care antidotes to treat overexposure to certain medications and toxins, and a licensing business that receives royalties related to BTG intellectual property and product license agreements. Upon the effectiveness of the scheme of arrangement, BTG became a wholly-owned subsidiary of Boston Scientific, and BTG shares no longer trade on the London Stock Exchange. Under the terms of the previously announced transaction, holders of BTG common shares will receive 840 pence in cash per share. The transaction would be funded with a combination of cash on hand and proceeds from debt financing entered into by Boston Scientific. The acquisition will enable Bravo Bidco to expand peripheral interventions portfolio with minimally-invasive treatments for cancers and vascular conditions. Goldman Sachs International, Deutsche Bank AG, J.P. Morgan Cazenove and Rothschild & Co acted as financial advisors where as Allen & Overy LLP acted as legal adviser to BTG, while Barclays acted as financial advisor where as Shearman & Sterling LLP, Simpson Thacher & Bartlett LLP, Arnold & Porter Kaye Scholer LLP and Travers Smith LLP acted as legal advisors, respectively, to Bravo Bidco. Deal History: Announced: On November 20, 2018, Boston Scientific reached an agreement on the terms of a recommended cash offer by its wholly-owned subsidiary, Bravo Bidco Ltd, for the acquisition of the entire issued and to be issued ordinary share capital (100%) of BTG plc, a company which develops and commercializes products used in minimally-invasive procedures targeting cancer and vascular diseases, as well as acute care pharmaceuticals, for GBP3.3 billion. Update: On December 12, 2018, BTG, Boston Scientific and Bidco entered into an amendment to the Co-operation Agreement to extend the date by which certain regulatory filings must be made in Spain, Germany and other relevant jurisdictions. The filing of the notification in respect of the Acquisition under the HSR Act was made yesterday. Update: On February 15, 2019, The Transaction has received merger control clearance in Germany under the German Act Against Restraints of Competition and the Taiwan Fair Trade Commission has terminated its investigation. Update: On February 28, 2019, The shareholders of BTG have approved in respect of the previously announced recommended cash offer to acquire the entire issued and to be issued ordinary share capital of BTG by Bravo Bidco, an indirect wholly-owned subsidiary of Boston Scientific. Update: On August 2, 2019, BTG and Boston Scientific are pleased to confirm that the Transaction has received merger control clearance from the US Federal Trade Commission under the HSR Act, on July 25, 2019 the CNMC issued a clearance decision under the Spanish Competition Act and on August 2, 2019, the Federal Competition Authority of Austria issued a clearance decision pursuant to Sec 11 Para 4 Austrian Cartel Act. | AI8: The acquisition will enable Bravo Bidco to expand peripheral interventions portfolio with minimally-invasive treatments for cancers and vascular conditions. | AL8: Unknown | AM8: Unknown | AS8: Bravo Bidco Ltd | AT8: BTG Ltd | AU8: Not reviewed | AV8: Not assessed | AW8: Unknown | AX8: Unknown | AY8: Unknown | AZ8: Unknown | BA8: Unknown | BB8: Unknown | BF8: Not collected | BG8: Not collected | BH8: Not defined | BI8: =IF($Q8="","",$Q8-3) -> 2016 | BJ8: =IF($Q8="","",$Q8-2) -> 2017 | BK8: =IF($Q8="","",$Q8-1) -> 2018 | BL8: =IF($Q8="","",$Q8+0) -> 2019 | BM8: =IF($Q8="","",$Q8+1) -> 2020 | BN8: =IF($Q8="","",$Q8+2) -> 2021 | BO8: =IF($Q8="","",$Q8+3) -> 2022 | EQ8: =IF(OR($EO8="",$EP8="",$EO8=0),"",$EP8/$EO8) | ES8: Unknown | ET8: Unknown | EU8: =IF(COUNT($DF8,$DG8,$DH8)=0,"",AVERAGE($DF8,$DG8,$DH8)) | EV8: =IF(COUNT($DJ8,$DK8,$DL8)=0,"",AVERAGE($DJ8,$DK8,$DL8)) | EW8: =IF(OR($EU8="",$EV8=""),"",$EV8-$EU8) | EX8: =IF(COUNT($DM8,$DN8,$DO8)=0,"",AVERAGE($DM8,$DN8,$DO8)) | EY8: =IF(COUNT($DQ8,$DR8,$DS8)=0,"",AVERAGE($DQ8,$DR8,$DS8)) | EZ8: =IF(OR($EX8="",$EY8=""),"",$EY8-$EX8) | FA8: =IF(COUNT($EA8,$EB8,$EC8)=0,"",AVERAGE($EA8,$EB8,$EC8)) | FB8: =IF(COUNT($EE8,$EF8,$EG8)=0,"",AVERAGE($EE8,$EF8,$EG8)) | FC8: =IF(OR($FA8="",$FB8=""),"",$FB8-$FA8) | FD8: =IF(COUNT($EH8,$EI8,$EJ8)=0,"",AVERAGE($EH8,$EI8,$EJ8)) | FE8: =IF(COUNT($EL8,$EM8,$EN8)=0,"",AVERAGE($EL8,$EM8,$EN8)) | FF8: =IF(OR($FD8="",$FE8=""),"",$FE8-$FD8) | FG8: =IF(COUNT($DF8,$DG8,$DH8,$DJ8,$DK8,$DL8,$DM8,$DN8,$DO8,$DQ8,$DR8,$DS8)=12,"Yes","No") -> No | FH8: =IF(COUNT($EA8,$EB8,$EC8,$EE8,$EF8,$EG8,$EH8,$EI8,$EJ8,$EL8,$EM8,$EN8)=12,"Yes","No") -> No | FI8: =IF(AND($M8="Include",OR($FG8="Yes",$FH8="Yes")),"Ready","Not ready") -> Not ready
A9: TRT-0007 | B9: 18 | C9: Candidate treatment group | D9: 1 | E9: DATA - Innovation driven deals.xlsx | F9: aphria acquires cc pharma | G9: Yes | H9: No | I9: No | J9: 1 | K9: Not started | L9: Review - majority | M9: Review | O9: 43409 | P9: 43474 | Q9: 2019 | R9: Q4 2018 | S9: Completed | T9: Aphria Acquires CC Pharma | U9: Mergers & Acquisitions | V9: Acquisition | W9: Majority Acquisition | X9: Germany | Y9: Majority Acquisition | AB9: Aphria Inc | AC9: aphria | AD9: CC Pharma GmbH | AE9: cc pharma | AF9: 28 | AG9: 28 | AH9: Aphria Inc., a global cannabis company, has completed the acquisition of CC Pharma GmbH, a distributor of pharmaceutical products. Under the terms of consideration, Aphria will pay EUR24.5 million in cash to CC Pharma at closing, with an earn-out multiple on future EBITDA of up to another EUR23.5 million following closing, if certain performance milestones are met. Aphria, through its subsidiary Aphria International, previously announced a supply agreement with CC Pharma to export approximately 1,200 kilograms of medical cannabis products from Canada to Germany. CC Pharma operates a production, repackaging and labeling facility at its headquarters in Densborn. The transaction enables Aphria to strengthen its end-to-end medical cannabis operations and infrastructure in Germany. Deal History: Announced: On November 5, 2011, Aphria announced its proposed acquisition of CC Pharma. | AI9: The transaction enables Aphria to strengthen its end-to-end medical cannabis operations and infrastructure in Germany. | AL9: Unknown | AM9: Unknown | AS9: Aphria Inc | AT9: CC Pharma GmbH | AU9: Not reviewed | AV9: Not assessed | AW9: Unknown | AX9: Unknown | AY9: Unknown | AZ9: Unknown | BA9: Unknown | BB9: Unknown | BF9: Not collected | BG9: Not collected | BH9: Not defined | BI9: =IF($Q9="","",$Q9-3) -> 2016 | BJ9: =IF($Q9="","",$Q9-2) -> 2017 | BK9: =IF($Q9="","",$Q9-1) -> 2018 | BL9: =IF($Q9="","",$Q9+0) -> 2019 | BM9: =IF($Q9="","",$Q9+1) -> 2020 | BN9: =IF($Q9="","",$Q9+2) -> 2021 | BO9: =IF($Q9="","",$Q9+3) -> 2022 | EQ9: =IF(OR($EO9="",$EP9="",$EO9=0),"",$EP9/$EO9) | ES9: Unknown | ET9: Unknown | EU9: =IF(COUNT($DF9,$DG9,$DH9)=0,"",AVERAGE($DF9,$DG9,$DH9)) | EV9: =IF(COUNT($DJ9,$DK9,$DL9)=0,"",AVERAGE($DJ9,$DK9,$DL9)) | EW9: =IF(OR($EU9="",$EV9=""),"",$EV9-$EU9) | EX9: =IF(COUNT($DM9,$DN9,$DO9)=0,"",AVERAGE($DM9,$DN9,$DO9)) | EY9: =IF(COUNT($DQ9,$DR9,$DS9)=0,"",AVERAGE($DQ9,$DR9,$DS9)) | EZ9: =IF(OR($EX9="",$EY9=""),"",$EY9-$EX9) | FA9: =IF(COUNT($EA9,$EB9,$EC9)=0,"",AVERAGE($EA9,$EB9,$EC9)) | FB9: =IF(COUNT($EE9,$EF9,$EG9)=0,"",AVERAGE($EE9,$EF9,$EG9)) | FC9: =IF(OR($FA9="",$FB9=""),"",$FB9-$FA9) | FD9: =IF(COUNT($EH9,$EI9,$EJ9)=0,"",AVERAGE($EH9,$EI9,$EJ9)) | FE9: =IF(COUNT($EL9,$EM9,$EN9)=0,"",AVERAGE($EL9,$EM9,$EN9)) | FF9: =IF(OR($FD9="",$FE9=""),"",$FE9-$FD9) | FG9: =IF(COUNT($DF9,$DG9,$DH9,$DJ9,$DK9,$DL9,$DM9,$DN9,$DO9,$DQ9,$DR9,$DS9)=12,"Yes","No") -> No | FH9: =IF(COUNT($EA9,$EB9,$EC9,$EE9,$EF9,$EG9,$EH9,$EI9,$EJ9,$EL9,$EM9,$EN9)=12,"Yes","No") -> No | FI9: =IF(AND($M9="Include",OR($FG9="Yes",$FH9="Yes")),"Ready","Not ready") -> Not ready
A10: TRT-0008 | B10: 19 | C10: Candidate treatment group | D10: 1 | E10: DATA - Innovation driven deals.xlsx | F10: ingenza acquires stake in amprologix | G10: Yes | H10: No | I10: No | J10: 1 | K10: Not started | L10: Exclude - minority | M10: Review | O10: 43363 | P10: 43363 | Q10: 2018 | R10: Q3 2018 | S10: Completed | T10: Ingenza Acquires Stake in Amprologix | U10: Mergers & Acquisitions | V10: Acquisition | W10: Minority Acquisition | X10: United Kingdom | Y10: Minority Acquisition | AB10: Ingenza Ltd | AC10: ingenza | AD10: Amprologix Ltd | AE10: amprologix | AG10: n/a | AH10: Ingenza Ltd, an industrial biotechnology and synthetic biology company, has acquired a stake in Amprologix Ltd, a spin-out company from the University of Plymouth. Amprologix develops and commercialises epidermicins, a new class of antibiotics capable of rapidly killing harmful bacteria, including methicillin-resistant Staphylococcus aureus (MRSA), Streptoccus and Enterococcus at very low doses. The acquisition enables Ingenza to discover and improve new antimicrobial classes. | AI10: The acquisition enables Ingenza to discover and improve new antimicrobial classes. | AL10: Unknown | AM10: Unknown | AS10: Ingenza Ltd | AT10: Amprologix Ltd | AU10: Not reviewed | AV10: Not assessed | AW10: Unknown | AX10: Unknown | AY10: Unknown | AZ10: Unknown | BA10: Unknown | BB10: Unknown | BF10: Not collected | BG10: Not collected | BH10: Not defined | BI10: =IF($Q10="","",$Q10-3) -> 2015 | BJ10: =IF($Q10="","",$Q10-2) -> 2016 | BK10: =IF($Q10="","",$Q10-1) -> 2017 | BL10: =IF($Q10="","",$Q10+0) -> 2018 | BM10: =IF($Q10="","",$Q10+1) -> 2019 | BN10: =IF($Q10="","",$Q10+2) -> 2020 | BO10: =IF($Q10="","",$Q10+3) -> 2021 | EQ10: =IF(OR($EO10="",$EP10="",$EO10=0),"",$EP10/$EO10) | ES10: Unknown | ET10: Unknown | EU10: =IF(COUNT($DF10,$DG10,$DH10)=0,"",AVERAGE($DF10,$DG10,$DH10)) | EV10: =IF(COUNT($DJ10,$DK10,$DL10)=0,"",AVERAGE($DJ10,$DK10,$DL10)) | EW10: =IF(OR($EU10="",$EV10=""),"",$EV10-$EU10) | EX10: =IF(COUNT($DM10,$DN10,$DO10)=0,"",AVERAGE($DM10,$DN10,$DO10)) | EY10: =IF(COUNT($DQ10,$DR10,$DS10)=0,"",AVERAGE($DQ10,$DR10,$DS10)) | EZ10: =IF(OR($EX10="",$EY10=""),"",$EY10-$EX10) | FA10: =IF(COUNT($EA10,$EB10,$EC10)=0,"",AVERAGE($EA10,$EB10,$EC10)) | FB10: =IF(COUNT($EE10,$EF10,$EG10)=0,"",AVERAGE($EE10,$EF10,$EG10)) | FC10: =IF(OR($FA10="",$FB10=""),"",$FB10-$FA10) | FD10: =IF(COUNT($EH10,$EI10,$EJ10)=0,"",AVERAGE($EH10,$EI10,$EJ10)) | FE10: =IF(COUNT($EL10,$EM10,$EN10)=0,"",AVERAGE($EL10,$EM10,$EN10)) | FF10: =IF(OR($FD10="",$FE10=""),"",$FE10-$FD10) | FG10: =IF(COUNT($DF10,$DG10,$DH10,$DJ10,$DK10,$DL10,$DM10,$DN10,$DO10,$DQ10,$DR10,$DS10)=12,"Yes","No") -> No | FH10: =IF(COUNT($EA10,$EB10,$EC10,$EE10,$EF10,$EG10,$EH10,$EI10,$EJ10,$EL10,$EM10,$EN10)=12,"Yes","No") -> No | FI10: =IF(AND($M10="Include",OR($FG10="Yes",$FH10="Yes")),"Ready","Not ready") -> Not ready
A11: TRT-0009 | B11: 20 | C11: Candidate treatment group | D11: 1 | E11: DATA - Innovation driven deals.xlsx | F11: telix pharma acquires atlab pharma for | G11: Yes | H11: No | I11: No | J11: 1 | K11: Not started | L11: Eligible - 100% | M11: Review | O11: 43354 | P11: 43354 | Q11: 2018 | R11: Q3 2018 | S11: Completed | T11: Telix Pharma Acquires Atlab Pharma for USD10 Million | U11: Mergers & Acquisitions | V11: Acquisition | W11: 100% Acquisition | X11: France | Y11: 100% Acquisition | AB11: Telix Pharmaceuticals Ltd | AC11: telix pharmaceuticals | AD11: ATLAB Pharma SAS | AE11: atlab pharma | AF11: 10 | AG11: 10 | AH11: Telix Pharmaceuticals Limited, a clinical-stage biotechnology company, has completed the acquisition of Atlab Pharma SAS, a biotechnology company, for a purchase consideration of USD10 million. Telix Pharma has exercised an option to acquire Atlab Pharma. A total of 14,840,000 shares were issued in consideration. The consideration of USD10 million is issued as USD9 million in Telix shares to Atlab shareholders, at USD0.89 per share, USD0.5 million in Telix shares to BZL, also at USD0.89 per share. These shares are paid to BZL as partial consideration for a significant reduction in royalty rates for the background IP, as a closing condition of the transaction, and USD0.5 million in warrants over Telix shares to BZL, with an exercise price of USD1.34 per share. As part of the transaction, Telix Pharma has also entered into a limited back - license with BZL Biologics LLC(BZL) for certain IP rights to support ongoing commercial research activities that are outside of the scope of product development focus for Telix Pharma. Prof. Jean-Francois Chatal (Atlab/ Universite de Nantes) and Prof. Neil Bander (BZL/ WCMC ) will continue to serve as members of Telix’s scientific advisory board. The transaction enables Telix Pharma to support potential indication expansion for TLX591, notably the combination use of anti-PSMA therapeutics in conjunction with anti-androgen drugs, further increasing the value and relevance of its TLX591 program; Atlab Pharma possesses rights to an extensive clinical data set in approximately 200 patients that is highly informative to the development of TLX591, including unpublished data around dose optimization schemes for antibody-based PSMA radiopharmaceuticals. This data may accelerate and further de-risk the future development of TLX591; Atlab Pharma and BZL, together, bring considerable knowledge and expertise to the Telix team; and Atlab possesses the rights and materials necessary to develop huJ591, the most widely clinically-studied anti-PSMA antibody. Telix will keep huJ591 as a back-up clinical drug candidate and continue to support several high-value academic collaborations around the use of this antibody that may also be informative to the future development of TLX591, including in non-prostate cancer indications. | AI11: The transaction enables Telix Pharma to support potential indication expansion for TLX591, notably the combination use of anti-PSMA therapeutics in conjunction with anti-androgen drugs, further increasing the value and relevance of its TLX591 program; Atlab Pharma possesses rights to an extensive clinical data set in approximately 200 patients that is highly informative to the development of TLX591, including unpublished data around dose optimization schemes for antibody-based PSMA radiopharmaceuticals. This data may accelerate and further de-risk the future development of TLX591; Atlab Pharma and BZL, together, bring considerable knowledge and expertise to the Telix team; and Atlab possesses the rights and materials necessary to develop huJ591, the most widely clinically-studied anti-PSMA antibody. Telix will keep huJ591 as a back-up clinical drug candidate and continue to support several high-value academic collaborations around the use of this antibody that may also be informative to the future development of TLX591, including in non-prostate cancer indications. | AL11: Unknown | AM11: Unknown | AS11: Telix Pharmaceuticals Ltd | AT11: ATLAB Pharma SAS | AU11: Not reviewed | AV11: Not assessed | AW11: Unknown | AX11: Unknown | AY11: Unknown | AZ11: Unknown | BA11: Unknown | BB11: Unknown | BF11: Not collected | BG11: Not collected | BH11: Not defined | BI11: =IF($Q11="","",$Q11-3) -> 2015 | BJ11: =IF($Q11="","",$Q11-2) -> 2016 | BK11: =IF($Q11="","",$Q11-1) -> 2017 | BL11: =IF($Q11="","",$Q11+0) -> 2018 | BM11: =IF($Q11="","",$Q11+1) -> 2019 | BN11: =IF($Q11="","",$Q11+2) -> 2020 | BO11: =IF($Q11="","",$Q11+3) -> 2021 | EQ11: =IF(OR($EO11="",$EP11="",$EO11=0),"",$EP11/$EO11) | ES11: Unknown | ET11: Unknown | EU11: =IF(COUNT($DF11,$DG11,$DH11)=0,"",AVERAGE($DF11,$DG11,$DH11)) | EV11: =IF(COUNT($DJ11,$DK11,$DL11)=0,"",AVERAGE($DJ11,$DK11,$DL11)) | EW11: =IF(OR($EU11="",$EV11=""),"",$EV11-$EU11) | EX11: =IF(COUNT($DM11,$DN11,$DO11)=0,"",AVERAGE($DM11,$DN11,$DO11)) | EY11: =IF(COUNT($DQ11,$DR11,$DS11)=0,"",AVERAGE($DQ11,$DR11,$DS11)) | EZ11: =IF(OR($EX11="",$EY11=""),"",$EY11-$EX11) | FA11: =IF(COUNT($EA11,$EB11,$EC11)=0,"",AVERAGE($EA11,$EB11,$EC11)) | FB11: =IF(COUNT($EE11,$EF11,$EG11)=0,"",AVERAGE($EE11,$EF11,$EG11)) | FC11: =IF(OR($FA11="",$FB11=""),"",$FB11-$FA11) | FD11: =IF(COUNT($EH11,$EI11,$EJ11)=0,"",AVERAGE($EH11,$EI11,$EJ11)) | FE11: =IF(COUNT($EL11,$EM11,$EN11)=0,"",AVERAGE($EL11,$EM11,$EN11)) | FF11: =IF(OR($FD11="",$FE11=""),"",$FE11-$FD11) | FG11: =IF(COUNT($DF11,$DG11,$DH11,$DJ11,$DK11,$DL11,$DM11,$DN11,$DO11,$DQ11,$DR11,$DS11)=12,"Yes","No") -> No | FH11: =IF(COUNT($EA11,$EB11,$EC11,$EE11,$EF11,$EG11,$EH11,$EI11,$EJ11,$EL11,$EM11,$EN11)=12,"Yes","No") -> No | FI11: =IF(AND($M11="Include",OR($FG11="Yes",$FH11="Yes")),"Ready","Not ready") -> Not ready
A12: TRT-0010 | B12: 21 | C12: Candidate treatment group | D12: 1 | E12: DATA - Innovation driven deals.xlsx | F12: sanofi acquires ablynx for | G12: Yes | H12: No | I12: No | J12: 1 | K12: Not started | L12: Eligible - 100% | M12: Review | O12: 43129 | P12: 43270 | Q12: 2018 | R12: Q1 2018 | S12: Completed | T12: Sanofi Acquires Ablynx for USD4.85 Billion | U12: Mergers & Acquisitions | V12: Acquisition | W12: 100% Acquisition | X12: Belgium | Y12: 100% Acquisition | Z12: Morgan Stanley , Lazard Inc , J.P. Morgan Securities LLC | AA12: Eubelius , Goodwin Procter LLP , Linklaters LLP , Weil, Gotshal & Manges LLP , NautaDutilh NV | AB12: Sanofi | AC12: sanofi | AD12: Ablynx NV | AE12: ablynx | AF12: 4847 | AG12: 4847 | AH12: Sanofi, a pharmaceutical company, has acquired all outstanding shares of Ablynx NV, a biopharmaceutical company focused on the discovery and development of nanobodies, for an aggregate equity value of approximately EUR3.9 billion (USD4.85 billion). The Squeeze-out period commenced on May 22, 2018, in accordance with applicable Belgian and the US law, following the acquisition by Sanofi of over 95% of the outstanding shares of Ablynx upon settlement of the initial acceptance period of its tender offer for Ablynx. On June 12, 2018, upon expiration of the Squeeze-out period, 2,893,201 shares (including 7,163 shares represented by ADSs) and 8 convertible bonds of Ablynx were tendered in the Squeeze-out. The securities tendered during the Squeeze-out period are expected to be settled on or about June 19, 2018. All shares (including all shares represented by ADSs) and all convertible bonds of Ablynx not tendered during the Squeeze-out are deemed transferred to Sanofi by operation of law. The funds required for the payment of the price thereof are kept with the Bank for official deposits (Deposito- en Consignatiekas / Caisse des depots et consignations). The former Ablynx holders of these Securities retain the right to receive EUR45 (USD55.92) per share (or ADS) and EUR393,700.78 per convertible bond. In order to receive these amounts, they must contact the bank for official deposits, where the funds will remain available. On June 13, 2018, The shares of Ablynx were delisted from the regulated market of Euronext Brussels, (ii) the ADSs were delisted from NASDAQ Global Select Market and (iii) the convertible bonds were delisted from the open market Frankfurt MTF (Freiverkehr). In accordance with the Belgian requirement of certainty of funds, Sanofi has entered into a bank credit facility, BNP Paribas Fortis SA/NA acting as the sole credit facility arranger. This transaction enables Sanofi to strengthen its R&D strategy with Nanobody technology platform and expands its rare blood disorders franchise with Ablynx’s late-stage investigational caplacizumab aTTP treatment. Morgan Stanley and Lazard Ltd. acted as financial advisors, Weil, Gotshal & Manges LLP and NautaDutilh NV acted as legal advisors to Sanofi; J.P. Morgan Securities LLC acted as financial advisor, while Eubelius CVBA, Goodwin Procter LLP and Linklaters LLP acted as legal advisors to Ablynx for the transaction. Deal History: Update: On May 14, 2018, Sanofi and Ablynx announced the results of the initial tender offer period of Sanofi’s previously announced tender offers to acquire all of the outstanding shares (including shares represented by American Depositary Shares (ADSs)), warrants and convertible bonds (together, the Securities) of Ablynx. Update: On March 29, 2018, Sanofi entered into definitive agreement with Ablynx to acquire all of the outstanding ordinary shares of Ablynx at a price per share of EUR45 (USD55.92) in cash, which represents an aggregate equity value of approximately EUR3.9 billion (USD4.85). The transaction was unanimously approved by both the Sanofi and Ablynx boards of directors. Sanofi and Ablynx have received an approval and publication of the tender offer documents and response by Ablynx’s Board of Directors. Sanofi confirmed that, as of the expiration of the initial acceptance period, which expired on May 4, 2018, a total of 71,972,994 shares (including 7,446,312 shares represented by ADSs), 2,594,841 warrants and 975 convertible bonds had been validly tendered into the offers and not withdrawn. Sanofi will own 95.60% of the outstanding shares of Ablynx on the settlement date of the offers, of which more than 90% were acquired through the offers. Sanofi further confirmed that the Minimum tender condition and the other conditions to the offers have been satisfied. Under the terms of the agreement, Sanofi will commence the tender offers to acquire all of the outstanding shares (includes shares represented by ADS), warrants and convertible bonds of Ablynx in cash for EUR45 (USD55.6) per share or ADS; EUR18.66 (USD23) - EUR41.79 (USD51.6) per warrant; and EUR0.39 (USD0.48) per convertible bond. Sanofi has complied with the formalities set forth in the Belgian takeover legislation and filed the mandatory documents with the FSMA. Update: On March 27, 2018, Sanofi and Ablynx have received prospectus approved by the Belgian Financial Services and Markets Authority (FSMA). Update: On March 1, 2018, Sanofi announced that the waiting period under the Hart-Scott-Rodino Antitrust Improvements Act of 1976 has expired and that Sanofi has received clearance from the Federal Cartel Office of Germany in accordance with the Act Against Restraints of Competition, applicable to the transaction. Earlier on January 5, 2018, Ablynx rejected the proposal from Novo Nordisk A/S for up to EUR30.5 (USD36.2) per share, including EUR28 (USD33.23) per share in cash and one CVR with total potential cash payments over time of up to EUR2.5 (USD2.97) per share or total equity valuation of EUR2.6 billion (USD3.09 billion), taking into account the interests of all its stakeholders, unanimously concluded that the proposal fundamentally undervalues Ablynx and its strong prospects for continued growth and value creation. | AI12: This transaction enables Sanofi to strengthen its R&D strategy with Nanobody technology platform and expands its rare blood disorders franchise with Ablynx’s late-stage investigational caplacizumab aTTP treatment. | AL12: Unknown | AM12: Yes | AN12: SAN FP | AS12: Sanofi | AT12: Ablynx NV | AU12: Not reviewed | AV12: Not assessed | AW12: Lens.org acquirer-side patent export imported; target patent export not supplied. | AX12: Unknown | AY12: Unknown | AZ12: Unknown | BA12: Unknown | BB12: Unknown | BE12: EUR | BF12: Complete | BG12: Complete event window — provisional; EP-only scope | BH12: EP-focused applicant-family export, 2015–2021; not directly comparable with multi-jurisdiction exports without harmonisation. | BI12: 2015 | BJ12: 2016 | BK12: 2017 | BL12: 2018 | BM12: 2019 | BN12: 2020 | BO12: 2021 | BP12: 34861 | BQ12: 34708 | BR12: 36221 | BS12: 35677 | BT12: 37631 | BU12: 37369 | BV12: 39175 | BW12: 7085 | BX12: 7489 | BY12: 7112 | BZ12: 5845 | CA12: 6882 | CB12: 7583 | CC12: 8729 | CD12: 4287 | CE12: 4709 | CF12: 8416 | CG12: 4306 | CH12: 2754 | CI12: 12294 | CJ12: 6223 | CK12: 102321 | CL12: 104672 | CM12: 99813 | CN12: 111408 | CO12: 112630 | CP12: 114413 | CQ12: 120242 | CR12: 16589 | CS12: 18589 | CT12: 15601 | CU12: 24640 | CV12: 25933 | CW12: 23675 | CX12: 22414 | CY12: 5082 | CZ12: 5172 | DA12: 5472 | DB12: 5894 | DC12: 6020 | DD12: 5530 | DE12: 5692 | DF12: 4.2932 | DG12: 4.5499 | DH12: 8.2314 | DI12: 4.0772 | DJ12: 2.4585 | DK12: 10.8297 | DL12: 5.304 | DM12: 16.4138 | DN12: 18.8256 | DO12: 16.0239 | DP12: 13.1065 | DQ12: 8.1077 | DR12: 37.7666 | DS12: 20.7428 | DT12: 16.2127 | DU12: 17.7593 | DV12: 15.6302 | DW12: 22.1169 | DX12: 23.0249 | DY12: 20.6926 | DZ12: 18.6407 | EA12: 15 | EB12: 28 | EC12: 36 | ED12: 38 | EE12: 42 | EF12: 20 | EG12: 13 | EH12: 9 | EI12: 4 | EJ12: 0 | EK12: 1 | EL12: 4 | EM12: 1 | EN12: 0 | EO12: 79 | EQ12: =IF(OR($EO12="",$EP12="",$EO12=0),"",$EP12/$EO12) | ES12: No | ET12: No | EU12: =IF(COUNT($DF12,$DG12,$DH12)=0,"",AVERAGE($DF12,$DG12,$DH12)) -> 5.6915 | EV12: =IF(COUNT($DJ12,$DK12,$DL12)=0,"",AVERAGE($DJ12,$DK12,$DL12)) -> 6.1974 | EW12: =IF(OR($EU12="",$EV12=""),"",$EV12-$EU12) -> 0.5059 | EX12: =IF(COUNT($DM12,$DN12,$DO12)=0,"",AVERAGE($DM12,$DN12,$DO12)) -> 17.087767 | EY12: =IF(COUNT($DQ12,$DR12,$DS12)=0,"",AVERAGE($DQ12,$DR12,$DS12)) -> 22.2057 | EZ12: =IF(OR($EX12="",$EY12=""),"",$EY12-$EX12) -> 5.1179333 | FA12: =IF(COUNT($EA12,$EB12,$EC12)=0,"",AVERAGE($EA12,$EB12,$EC12)) -> 26.333333 | FB12: =IF(COUNT($EE12,$EF12,$EG12)=0,"",AVERAGE($EE12,$EF12,$EG12)) -> 25 | FC12: =IF(OR($FA12="",$FB12=""),"",$FB12-$FA12) -> -1.3333333 | FD12: =IF(COUNT($EH12,$EI12,$EJ12)=0,"",AVERAGE($EH12,$EI12,$EJ12)) -> 4.3333333 | FE12: =IF(COUNT($EL12,$EM12,$EN12)=0,"",AVERAGE($EL12,$EM12,$EN12)) -> 1.6666667 | FF12: =IF(OR($FD12="",$FE12=""),"",$FE12-$FD12) -> -2.6666667 | FG12: =IF(COUNT($DF12,$DG12,$DH12,$DJ12,$DK12,$DL12,$DM12,$DN12,$DO12,$DQ12,$DR12,$DS12)=12,"Yes","No") -> Yes | FH12: =IF(COUNT($EA12,$EB12,$EC12,$EE12,$EF12,$EG12,$EH12,$EI12,$EJ12,$EL12,$EM12,$EN12)=12,"Yes","No") -> Yes | FI12: =IF(AND($M12="Include",OR($FG12="Yes",$FH12="Yes")),"Ready","Not ready") -> Not ready
A13: TRT-0011 | B13: 22 | C13: Candidate treatment group | D13: 1 | E13: DATA - Innovation driven deals.xlsx | F13: takeda pharma acquires tigenix for | G13: Yes | H13: No | I13: No | J13: 1 | K13: Not started | L13: Eligible - 100% | M13: Review | O13: 43105 | P13: 43312 | Q13: 2018 | R13: Q1 2018 | S13: Completed | T13: Takeda Pharma Acquires TiGenix for USD626.4 Million | U13: Mergers & Acquisitions | V13: Acquisition | W13: 100% Acquisition | X13: Belgium | Y13: 100% Acquisition | Z13: Cowen and Company, LLC (Inactive) , Centerview Partners UK LLP | AA13: Covington & Burling LLP , DLA Piper US LLP , Davis Polk & Wardwell LLP , DLA Piper UK LLP , Osborne Clarke N.V. | AB13: Takeda Pharmaceutical Co Ltd | AC13: takeda pharmaceutical | AD13: TiGenix NV | AE13: tigenix | AF13: 626 | AG13: 626 | AH13: Takeda Pharmaceutical Co. Ltd., a pharmaceutical company, has completed the acquisition of TiGenix NV, a biopharmaceutical company developing stem cell therapies for serious medical conditions, for a purchase consideration of approximately EUR520 million (USD626.4 million). Takeda Pharma intends to fund the transaction cost from existing cash balances. Pursuant to the transaction, TiGenix becomes a wholly owned subsidiary of Takeda. On June 6, 2018, Takeda Pharma announced the results of the first acceptance period of Takeda’s previously announced tender offer in cash for all outstanding ordinary shares, warrants and American Depositary Shares (ADSs) and together with the ordinary shares and the warrants, the securities) of TiGenix that are not yet owned by Takeda and its affiliates, which expired as scheduled on May 31, 2018. The second acceptance period for the Belgian offer will commence on June 20, 2018, and the second acceptance period for the US offer will commence today, June 6, 2018, and is scheduled to expire for both the Belgian offer and the US offer, subject to any extension, on July 3, 2018, respectively. The results of the second acceptance period are expected to be published on July 6, 2018. Payment for the ordinary shares, warrants and ADSs validly tendered and not withdrawn in the second acceptance period is currently expected to commence on July 10, 2018. During the second acceptance period, holders of ordinary shares, warrants and ADSs can tender their securities in the bid by following the instructions set out in the prospectus or the tender offer statement on schedule TO, as applicable to them. On April 25, 2018, Takeda Pharma announced that the first acceptance period of tender offer in cash for all outstanding ordinary shares. warrants and ADSs of TiGenix that are not yet owned by Takeda and its affiliates, at an acquisition price of EUR1.78 per ordinary share in cash; EUR35.60 (USD42.8) per ADS in cash and an amount per warrant in cash depending on the strike price and maturity of such Warrant, will commence on April 30, 2018. The first acceptance period for the bid will start on April 30, 2018 and is scheduled to expire, subject to any extension, on May 31, 2018. The results of the first acceptance period are expected to be published on June 6, 2018. Payment for the ordinary shares, warrants and ADSs validly tendered and not withdrawn in the first acceptance period is currently scheduled for June 8, 2018 although the Belgian offer and the US offer may have different payment dates. During the first acceptance period, holders of ordinary shares, warrants and ADSs can tender their securities in the bid by following the instructions set out in the prospectus or the tender offer statement on schedule TO, as applicable to them. Pursuant to the transaction, Takeda Pharma intends to acquire 100% of the securities with voting rights or giving access to voting rights of TiGenix not already owned by Takeda Pharma or its affiliates at an acquisition price of EUR1.78 (USD2.14) per share in cash and an equivalent price per American Depositary Share (ADS), warrant and convertible bond, representing a transaction value of approximately EUR520 million (USD626.44 million) on a fully diluted basis. The transaction is structured as an all cash voluntary public takeover bid by Takeda Pharma with respect to 100% of the securities with voting rights or giving access to voting rights of TiGenix that are not already owned by Takeda Pharma or its affiliates. Takeda Pharma and TiGenix entered into an offer and support agreement confirming TiGenix’s support and the terms and conditions of the bid. Gri-Cel SA, holding 32,238,178 TiGenix shares, and its affiliate Grifols Worldwide Operations Ltd., holding 7,189,800 TiGenix shares in the form of ADS, have irrevocably confirmed that they will tender their shares and ADSs into the potential public takeover bid. The acquisition extends an existing exclusive ex-US license, development and commercialization agreement between Takeda and TiGenix to develop and commercialize Cx601 (darvadstrocel) entered in July 2016. This acquisition enables Takeda Pharma to expand its late stage gastroenterology pipeline and strengthen presence in the US specialty care market. Centerview Partners UK LLP acted as financial advisor, DLA Piper UK LLP and DLA Piper US LLP acted as legal advisor to Takeda Pharma; Cowen and Company, LLC acted as financial advisor, while Osborne Clarke CVBA and Davis Polk & Wardwell LLP acted as legal advisor to Tingenix for the transaction. Deal History: Announced: On January 5, 2018, Takeda Pharma intends to acquire TiGenix, for a purchase consideration of approximately EUR520 million (USD626.4 million). Takeda Pharma intends to fund the transaction cost from existing cash balances. Takeda Pharma has also entered into an offer and support agreement with TiGenix which provides for a recommended potential voluntary public takeover bid for TiGenix. The agreement has been unanimously supported by the TiGenix board of directors (including its CEO). The bid will be comprised of two separate offers (i) an offer to all holders of ordinary shares and warrants in accordance with the applicable law in Belgium (Belgian offer), and (ii) an offer to holders of ordinary shares who are resident in the US in accordance with applicable the US law and to holders of ADSs wherever located (the US offer). Following closing of the potential voluntary public takeover bid, Takeda Pharma intends to launch a squeeze-out if the applicable conditions for such squeeze-out are met to delist the shares of TiGenix from Euronext Brussels and NASDAQ. After the squeeze-out, TiGenix would become a wholly-owned subsidiary of Takeda. | AI13: This acquisition enables Takeda Pharma to expand its late stage gastroenterology pipeline and strengthen presence in the US specialty care market. | AL13: Unknown | AM13: Unknown | AS13: Takeda Pharmaceutical Co Ltd | AT13: TiGenix NV | AU13: Not reviewed | AV13: Not assessed | AW13: Unknown | AX13: Unknown | AY13: Unknown | AZ13: Unknown | BA13: Unknown | BB13: Unknown | BF13: Not collected | BG13: Not collected | BH13: Not defined | BI13: =IF($Q13="","",$Q13-3) -> 2015 | BJ13: =IF($Q13="","",$Q13-2) -> 2016 | BK13: =IF($Q13="","",$Q13-1) -> 2017 | BL13: =IF($Q13="","",$Q13+0) -> 2018 | BM13: =IF($Q13="","",$Q13+1) -> 2019 | BN13: =IF($Q13="","",$Q13+2) -> 2020 | BO13: =IF($Q13="","",$Q13+3) -> 2021 | EQ13: =IF(OR($EO13="",$EP13="",$EO13=0),"",$EP13/$EO13) | ES13: Unknown | ET13: Unknown | EU13: =IF(COUNT($DF13,$DG13,$DH13)=0,"",AVERAGE($DF13,$DG13,$DH13)) | EV13: =IF(COUNT($DJ13,$DK13,$DL13)=0,"",AVERAGE($DJ13,$DK13,$DL13)) | EW13: =IF(OR($EU13="",$EV13=""),"",$EV13-$EU13) | EX13: =IF(COUNT($DM13,$DN13,$DO13)=0,"",AVERAGE($DM13,$DN13,$DO13)) | EY13: =IF(COUNT($DQ13,$DR13,$DS13)=0,"",AVERAGE($DQ13,$DR13,$DS13)) | EZ13: =IF(OR($EX13="",$EY13=""),"",$EY13-$EX13) | FA13: =IF(COUNT($EA13,$EB13,$EC13)=0,"",AVERAGE($EA13,$EB13,$EC13)) | FB13: =IF(COUNT($EE13,$EF13,$EG13)=0,"",AVERAGE($EE13,$EF13,$EG13)) | FC13: =IF(OR($FA13="",$FB13=""),"",$FB13-$FA13) | FD13: =IF(COUNT($EH13,$EI13,$EJ13)=0,"",AVERAGE($EH13,$EI13,$EJ13)) | FE13: =IF(COUNT($EL13,$EM13,$EN13)=0,"",AVERAGE($EL13,$EM13,$EN13)) | FF13: =IF(OR($FD13="",$FE13=""),"",$FE13-$FD13) | FG13: =IF(COUNT($DF13,$DG13,$DH13,$DJ13,$DK13,$DL13,$DM13,$DN13,$DO13,$DQ13,$DR13,$DS13)=12,"Yes","No") -> No | FH13: =IF(COUNT($EA13,$EB13,$EC13,$EE13,$EF13,$EG13,$EH13,$EI13,$EJ13,$EL13,$EM13,$EN13)=12,"Yes","No") -> No | FI13: =IF(AND($M13="Include",OR($FG13="Yes",$FH13="Yes")),"Ready","Not ready") -> Not ready
